Workbook

Sheet 模板说明
A1: 分析方法验证原始数据计算模板
A3: 模板版本 | B3: 2.0
A4: 最大杂质数 | B4: 10
A5: 工作簿用途 | B5: 验证报告原始数据与计算结果
A6: 输入颜色 | B6: 浅黄色
A7: 公式颜色 | B7: 浅绿色
A8: 保护密码 | B8: report-template
A11: 使用顺序
A12: 1. | B12: 先在“杂质清单”登记最多10个杂质，再到各结果表通过 impurity_id 下拉选择。
A13: 2. | B13: 黄色单元格是唯一允许录入的位置；绿色单元格由公式计算，不能覆盖。
A14: 3. | B14: 每行只代表一条测定记录；不同杂质、不同序列或不同条件不得写在同一行。
A15: 4. | B15: 不要新增列、改写英文字段名或在表外记录数据；行数不足时由管理员扩展模板。
A16: 5. | B16: 本模板不录入结论、验证项目名称、实验过程、接受标准、仪器或溶液配制信息。

Sheet 杂质清单
A1: 杂质清单
A2: impurity_id | B2: impurity_name | C2: short_name | D2: limit_ppm | E2: limit_concentration | F2: api_concentration | G2: enabled | H2: note
A3: 杂质编号 | B3: 杂质名称 | C3: 简称 | D3: 限度（ppm） | E3: 限度浓度（ng/ml） | F3: 供试品API浓度（mg/ml） | G3: 启用 | H3: 备注
A4: IMP-01 | G4: 是
A5: IMP-02 | G5: 是
A6: IMP-03 | G6: 是
A7: IMP-04 | G7: 否
A8: IMP-05 | G8: 否
A9: IMP-06 | G9: 否
A10: IMP-07 | G10: 否
A11: IMP-08 | G11: 否
A12: IMP-09 | G12: 否
A13: IMP-10 | G13: 否

Sheet AI数据索引
A1: table_code | B1: 工作表 | C1: 数据区域 | D1: 结构类型 | E1: 稳定字段 | F1: 目标标准JSON路径
A2: impurities | B2: 杂质清单 | C2: A2:H13 | D2: 纵向明细表 | E2: impurity_id,impurity_name,short_name,limit_ppm,limit_concentration,api_concentration,enabled,note | F2: $.impurities[*]
A3: systemSuitability | B3: 系统适用性结果 | C3: A2:F63 | D3: 纵向明细表 | E3: impurity_id,sequence,retention_time,peak_area,retention_time_rsd,peak_area_rsd | F3: $.systemSuitability[*]
A4: specificity | B4: 专属性结果 | C4: A2:D103 | D4: 纵向明细表 | E4: impurity_id,solution_name,retention_time,peak_area | F4: $.specificity[*]
A5: lodLoq | B5: 检测限定量限结果 | C5: A2:I93 | D5: 纵向明细表 | E5: impurity_id,result_type,sequence,sn_ratio,peak_area,concentration,sample_content,limit_percentage,peak_area_rsd | F5: $.lod[*] / $.loq[*]（按 result_type 拆分）
A6: linearityPreparation | B6: 线性溶液数值 | C6: A2:H103 | D6: 纵向明细表 | E6: impurity_id,run_type,solution_name,stock_concentration,aliquot_volume,final_volume,theoretical_concentration,limit_percentage | F6: $.linearityPreparation[*] / $.intermediateLinearityPreparation[*]（按 run_type 拆分）
A7: linearity | B7: 线性与范围结果 | C7: A2:L103 | D7: 纵向明细表 | E7: impurity_id,run_type,level,actual_concentration,peak_area,predicted_peak_area,residual,relative_residual,slope,intercept,correlation_coefficient,intercept_ratio | F7: $.linearity[*] / $.intermediateLinearity[*]（按 run_type 拆分）
A8: repeatability | B8: 重复性结果 | C8: A2:M63 | D8: 纵向明细表 | E8: impurity_id,sequence,gross_weight,tare_weight,api_weight,retention_time,peak_area,measured_concentration,sample_content,retention_time_rsd,content_rsd,content_ci_low,content_ci_high | F8: $.repeatability[*]
A9: intermediatePrecision | B9: 中间精密度结果 | C9: A2:N123 | D9: 纵向明细表 | E9: impurity_id,operator_or_day,sequence,gross_weight,tare_weight,api_weight,retention_time,peak_area,measured_concentration,sample_content,retention_time_rsd,content_rsd,content_ci_low,content_ci_high | F9: $.intermediatePrecision[*]
A10: accuracy | B10: 准确度结果 | C10: A2:M153 | D10: 纵向明细表 | E10: impurity_id,record_type,level,sequence,api_weight,peak_area,measured_concentration,measured_amount,blank_amount,added_amount,recovery,average_recovery,recovery_rsd | F10: $.blankAmount[*] / $.accuracy[*]（按 record_type 拆分）
A11: solutionStability | B11: 溶液稳定性结果 | C11: A2:F103 | D11: 纵向明细表 | E11: impurity_id,time_point,reference_concentration,reference_ratio,spiked_concentration,spiked_ratio | F11: $.solutionStability[*]
A12: robustness | B12: 耐用性结果 | C12: A2:K123 | D12: 纵向明细表 | E12: impurity_id,column_no,solution_name,level,actual_concentration,peak_area,spiked_measured_concentration,slope,intercept,correlation_coefficient,column_concentration_ratio | F12: $.robustnessSpecificity[*] / $.robustnessResult[*]

Sheet 录入规则
A1: 工作表 | B1: 允许录入区域 | C1: 填写规则 | D1: 禁止操作
A2: 杂质清单 | B2: 第4-13行黄色区域 | C2: 固定10个杂质槽位；编号不可修改，其余黄色字段按项目填写 | D2: 表头、公式、绿色区域和表外区域均锁定
A3: 系统适用性结果 | B3: 第4-63行黄色区域 | C3: 每个启用杂质固定6行，最多10个杂质，共60行 | D3: 表头、公式、绿色区域和表外区域均锁定
A4: 专属性结果 | B4: 第4-103行黄色区域 | C4: 每个杂质最多10种溶液，每行一个杂质-溶液结果 | D4: 表头、公式、绿色区域和表外区域均锁定
A5: 检测限定量限结果 | B5: 第4-93行黄色区域 | C5: 每个杂质3行LOD和6行LOQ；结果类型必须选择LOD或LOQ | D5: 表头、公式、绿色区域和表外区域均锁定
A6: 线性溶液数值 | B6: 第4-103行黄色区域 | C6: 每个杂质的初始和中间精密度线性各填写C1-C5数值 | D6: 表头、公式、绿色区域和表外区域均锁定
A7: 线性与范围结果 | B7: 第4-103行黄色区域 | C7: 每个杂质的初始线性和中间精密度线性各固定C1-C5五行 | D7: 表头、公式、绿色区域和表外区域均锁定
A8: 重复性结果 | B8: 第4-63行黄色区域 | C8: 每个杂质每组固定6份；中间精密度使用A/B两组，共12份 | D8: 表头、公式、绿色区域和表外区域均锁定
A9: 中间精密度结果 | B9: 第4-123行黄色区域 | C9: 每个杂质每组固定6份；中间精密度使用A/B两组，共12份 | D9: 表头、公式、绿色区域和表外区域均锁定
A10: 准确度结果 | B10: 第4-153行黄色区域 | C10: 每个杂质先填空白本底，再按LOQ/50%/100%/150%各3份填写 | D10: 表头、公式、绿色区域和表外区域均锁定
A11: 溶液稳定性结果 | B11: 第4-103行黄色区域 | C11: 每个杂质最多10个时间点，必须包含0h基准 | D11: 表头、公式、绿色区域和表外区域均锁定
A12: 耐用性结果 | B12: 第4-123行黄色区域 | C12: 每个杂质每根色谱柱固定C1-C5和加标溶液数据 | D12: 表头、公式、绿色区域和表外区域均锁定

Sheet 系统适用性结果
A1: 系统适用性结果
A2: impurity_id | B2: sequence | C2: retention_time | D2: peak_area | E2: retention_time_rsd | F2: peak_area_rsd
A3: 杂质编号 | B3: No. | C3: 保留时间（min） | D3: 峰面积 | E3: 保留时间RSD（%） | F3: 峰面积RSD（%）
A4: IMP-01 | B4: 1 | E4: =IFERROR(ROUND(STDEV(C4:C9)/AVERAGE(C4:C9)*100,2),"") | F4: =IFERROR(ROUND(STDEV(D4:D9)/AVERAGE(D4:D9)*100,2),"")
A5: IMP-01 | B5: 2 | E5: =IFERROR(ROUND(STDEV(C4:C9)/AVERAGE(C4:C9)*100,2),"") | F5: =IFERROR(ROUND(STDEV(D4:D9)/AVERAGE(D4:D9)*100,2),"")
A6: IMP-01 | B6: 3 | E6: =IFERROR(ROUND(STDEV(C4:C9)/AVERAGE(C4:C9)*100,2),"") | F6: =IFERROR(ROUND(STDEV(D4:D9)/AVERAGE(D4:D9)*100,2),"")
A7: IMP-01 | B7: 4 | E7: =IFERROR(ROUND(STDEV(C4:C9)/AVERAGE(C4:C9)*100,2),"") | F7: =IFERROR(ROUND(STDEV(D4:D9)/AVERAGE(D4:D9)*100,2),"")
A8: IMP-01 | B8: 5 | E8: =IFERROR(ROUND(STDEV(C4:C9)/AVERAGE(C4:C9)*100,2),"") | F8: =IFERROR(ROUND(STDEV(D4:D9)/AVERAGE(D4:D9)*100,2),"")
A9: IMP-01 | B9: 6 | E9: =IFERROR(ROUND(STDEV(C4:C9)/AVERAGE(C4:C9)*100,2),"") | F9: =IFERROR(ROUND(STDEV(D4:D9)/AVERAGE(D4:D9)*100,2),"")
A10: IMP-02 | B10: 1 | E10: =IFERROR(ROUND(STDEV(C10:C15)/AVERAGE(C10:C15)*100,2),"") | F10: =IFERROR(ROUND(STDEV(D10:D15)/AVERAGE(D10:D15)*100,2),"")
A11: IMP-02 | B11: 2 | E11: =IFERROR(ROUND(STDEV(C10:C15)/AVERAGE(C10:C15)*100,2),"") | F11: =IFERROR(ROUND(STDEV(D10:D15)/AVERAGE(D10:D15)*100,2),"")
A12: IMP-02 | B12: 3 | E12: =IFERROR(ROUND(STDEV(C10:C15)/AVERAGE(C10:C15)*100,2),"") | F12: =IFERROR(ROUND(STDEV(D10:D15)/AVERAGE(D10:D15)*100,2),"")
A13: IMP-02 | B13: 4 | E13: =IFERROR(ROUND(STDEV(C10:C15)/AVERAGE(C10:C15)*100,2),"") | F13: =IFERROR(ROUND(STDEV(D10:D15)/AVERAGE(D10:D15)*100,2),"")
A14: IMP-02 | B14: 5 | E14: =IFERROR(ROUND(STDEV(C10:C15)/AVERAGE(C10:C15)*100,2),"") | F14: =IFERROR(ROUND(STDEV(D10:D15)/AVERAGE(D10:D15)*100,2),"")
A15: IMP-02 | B15: 6 | E15: =IFERROR(ROUND(STDEV(C10:C15)/AVERAGE(C10:C15)*100,2),"") | F15: =IFERROR(ROUND(STDEV(D10:D15)/AVERAGE(D10:D15)*100,2),"")
A16: IMP-03 | B16: 1 | E16: =IFERROR(ROUND(STDEV(C16:C21)/AVERAGE(C16:C21)*100,2),"") | F16: =IFERROR(ROUND(STDEV(D16:D21)/AVERAGE(D16:D21)*100,2),"")
A17: IMP-03 | B17: 2 | E17: =IFERROR(ROUND(STDEV(C16:C21)/AVERAGE(C16:C21)*100,2),"") | F17: =IFERROR(ROUND(STDEV(D16:D21)/AVERAGE(D16:D21)*100,2),"")
A18: IMP-03 | B18: 3 | E18: =IFERROR(ROUND(STDEV(C16:C21)/AVERAGE(C16:C21)*100,2),"") | F18: =IFERROR(ROUND(STDEV(D16:D21)/AVERAGE(D16:D21)*100,2),"")
A19: IMP-03 | B19: 4 | E19: =IFERROR(ROUND(STDEV(C16:C21)/AVERAGE(C16:C21)*100,2),"") | F19: =IFERROR(ROUND(STDEV(D16:D21)/AVERAGE(D16:D21)*100,2),"")
A20: IMP-03 | B20: 5 | E20: =IFERROR(ROUND(STDEV(C16:C21)/AVERAGE(C16:C21)*100,2),"") | F20: =IFERROR(ROUND(STDEV(D16:D21)/AVERAGE(D16:D21)*100,2),"")
A21: IMP-03 | B21: 6 | E21: =IFERROR(ROUND(STDEV(C16:C21)/AVERAGE(C16:C21)*100,2),"") | F21: =IFERROR(ROUND(STDEV(D16:D21)/AVERAGE(D16:D21)*100,2),"")
A22: IMP-04 | B22: 1 | E22: =IFERROR(ROUND(STDEV(C22:C27)/AVERAGE(C22:C27)*100,2),"") | F22: =IFERROR(ROUND(STDEV(D22:D27)/AVERAGE(D22:D27)*100,2),"")
A23: IMP-04 | B23: 2 | E23: =IFERROR(ROUND(STDEV(C22:C27)/AVERAGE(C22:C27)*100,2),"") | F23: =IFERROR(ROUND(STDEV(D22:D27)/AVERAGE(D22:D27)*100,2),"")
A24: IMP-04 | B24: 3 | E24: =IFERROR(ROUND(STDEV(C22:C27)/AVERAGE(C22:C27)*100,2),"") | F24: =IFERROR(ROUND(STDEV(D22:D27)/AVERAGE(D22:D27)*100,2),"")
A25: IMP-04 | B25: 4 | E25: =IFERROR(ROUND(STDEV(C22:C27)/AVERAGE(C22:C27)*100,2),"") | F25: =IFERROR(ROUND(STDEV(D22:D27)/AVERAGE(D22:D27)*100,2),"")
A26: IMP-04 | B26: 5 | E26: =IFERROR(ROUND(STDEV(C22:C27)/AVERAGE(C22:C27)*100,2),"") | F26: =IFERROR(ROUND(STDEV(D22:D27)/AVERAGE(D22:D27)*100,2),"")
A27: IMP-04 | B27: 6 | E27: =IFERROR(ROUND(STDEV(C22:C27)/AVERAGE(C22:C27)*100,2),"") | F27: =IFERROR(ROUND(STDEV(D22:D27)/AVERAGE(D22:D27)*100,2),"")
A28: IMP-05 | B28: 1 | E28: =IFERROR(ROUND(STDEV(C28:C33)/AVERAGE(C28:C33)*100,2),"") | F28: =IFERROR(ROUND(STDEV(D28:D33)/AVERAGE(D28:D33)*100,2),"")
A29: IMP-05 | B29: 2 | E29: =IFERROR(ROUND(STDEV(C28:C33)/AVERAGE(C28:C33)*100,2),"") | F29: =IFERROR(ROUND(STDEV(D28:D33)/AVERAGE(D28:D33)*100,2),"")
A30: IMP-05 | B30: 3 | E30: =IFERROR(ROUND(STDEV(C28:C33)/AVERAGE(C28:C33)*100,2),"") | F30: =IFERROR(ROUND(STDEV(D28:D33)/AVERAGE(D28:D33)*100,2),"")
A31: IMP-05 | B31: 4 | E31: =IFERROR(ROUND(STDEV(C28:C33)/AVERAGE(C28:C33)*100,2),"") | F31: =IFERROR(ROUND(STDEV(D28:D33)/AVERAGE(D28:D33)*100,2),"")
A32: IMP-05 | B32: 5 | E32: =IFERROR(ROUND(STDEV(C28:C33)/AVERAGE(C28:C33)*100,2),"") | F32: =IFERROR(ROUND(STDEV(D28:D33)/AVERAGE(D28:D33)*100,2),"")
A33: IMP-05 | B33: 6 | E33: =IFERROR(ROUND(STDEV(C28:C33)/AVERAGE(C28:C33)*100,2),"") | F33: =IFERROR(ROUND(STDEV(D28:D33)/AVERAGE(D28:D33)*100,2),"")
A34: IMP-06 | B34: 1 | E34: =IFERROR(ROUND(STDEV(C34:C39)/AVERAGE(C34:C39)*100,2),"") | F34: =IFERROR(ROUND(STDEV(D34:D39)/AVERAGE(D34:D39)*100,2),"")
A35: IMP-06 | B35: 2 | E35: =IFERROR(ROUND(STDEV(C34:C39)/AVERAGE(C34:C39)*100,2),"") | F35: =IFERROR(ROUND(STDEV(D34:D39)/AVERAGE(D34:D39)*100,2),"")
A36: IMP-06 | B36: 3 | E36: =IFERROR(ROUND(STDEV(C34:C39)/AVERAGE(C34:C39)*100,2),"") | F36: =IFERROR(ROUND(STDEV(D34:D39)/AVERAGE(D34:D39)*100,2),"")
A37: IMP-06 | B37: 4 | E37: =IFERROR(ROUND(STDEV(C34:C39)/AVERAGE(C34:C39)*100,2),"") | F37: =IFERROR(ROUND(STDEV(D34:D39)/AVERAGE(D34:D39)*100,2),"")
A38: IMP-06 | B38: 5 | E38: =IFERROR(ROUND(STDEV(C34:C39)/AVERAGE(C34:C39)*100,2),"") | F38: =IFERROR(ROUND(STDEV(D34:D39)/AVERAGE(D34:D39)*100,2),"")
A39: IMP-06 | B39: 6 | E39: =IFERROR(ROUND(STDEV(C34:C39)/AVERAGE(C34:C39)*100,2),"") | F39: =IFERROR(ROUND(STDEV(D34:D39)/AVERAGE(D34:D39)*100,2),"")
A40: IMP-07 | B40: 1 | E40: =IFERROR(ROUND(STDEV(C40:C45)/AVERAGE(C40:C45)*100,2),"") | F40: =IFERROR(ROUND(STDEV(D40:D45)/AVERAGE(D40:D45)*100,2),"")
...

Sheet 专属性结果
A1: 专属性结果
A2: impurity_id | B2: solution_name | C2: retention_time | D2: peak_area
A3: 杂质编号 | B3: 溶液名称 | C3: 保留时间（min） | D3: 峰面积
A4: IMP-01
A5: IMP-01
A6: IMP-01
A7: IMP-01
A8: IMP-01
A9: IMP-01
A10: IMP-01
A11: IMP-01
A12: IMP-01
A13: IMP-01
A14: IMP-02
A15: IMP-02
... A103: IMP-10

Sheet 检测限定量限结果
A1: 检测限定量限结果
A2: impurity_id | B2: result_type | C2: sequence | D2: sn_ratio | E2: peak_area | F2: concentration | G2: sample_content | H2: limit_percentage | I2: peak_area_rsd
A3: 杂质编号 | B3: 结果类型 | C3: No. | D3: 信噪比S/N | E3: 峰面积 | F3: 浓度（ng/ml） | G3: 相当于供试品中含量（ppm） | H3: 占限度百分比（%） | I3: 峰面积RSD（%）
A4: IMP-01 | B4: LOD | C4: 1 | G4: =IFERROR(ROUND(F4/VLOOKUP(A4,'杂质清单'!$A$4:$F$13,6,FALSE),2),"") | H4: =IFERROR(ROUND(G4/VLOOKUP(A4,'杂质清单'!$A$4:$F$13,4,FALSE)*100,2),"") | I4: =IF(B4<>"LOQ","",IFERROR(ROUND(STDEV(E7:E12)/AVERAGE(E7:E12)*100,2),""))
A5: IMP-01 | B5: LOD | C5: 2 | G5: =IFERROR(ROUND(F5/VLOOKUP(A5,'杂质清单'!$A$4:$F$13,6,FALSE),2),"") | H5: =IFERROR(ROUND(G5/VLOOKUP(A5,'杂质清单'!$A$4:$F$13,4,FALSE)*100,2),"") | I5: =IF(B5<>"LOQ","",IFERROR(ROUND(STDEV(E7:E12)/AVERAGE(E7:E12)*100,2),""))
A6: IMP-01 | B6: LOD | C6: 3 | G6: =IFERROR(ROUND(F6/VLOOKUP(A6,'杂质清单'!$A$4:$F$13,6,FALSE),2),"") | H6: =IFERROR(ROUND(G6/VLOOKUP(A6,'杂质清单'!$A$4:$F$13,4,FALSE)*100,2),"") | I6: =IF(B6<>"LOQ","",IFERROR(ROUND(STDEV(E7:E12)/AVERAGE(E7:E12)*100,2),""))
A7: IMP-01 | B7: LOQ | C7: 1 | G7: =IFERROR(ROUND(F7/VLOOKUP(A7,'杂质清单'!$A$4:$F$13,6,FALSE),2),"") | H7: =IFERROR(ROUND(G7/VLOOKUP(A7,'杂质清单'!$A$4:$F$13,4,FALSE)*100,2),"") | I7: =IF(B7<>"LOQ","",IFERROR(ROUND(STDEV(E7:E12)/AVERAGE(E7:E12)*100,2),""))
A8: IMP-01 | B8: LOQ | C8: 2 | G8: =IFERROR(ROUND(F8/VLOOKUP(A8,'杂质清单'!$A$4:$F$13,6,FALSE),2),"") | H8: =IFERROR(ROUND(G8/VLOOKUP(A8,'杂质清单'!$A$4:$F$13,4,FALSE)*100,2),"") | I8: =IF(B8<>"LOQ","",IFERROR(ROUND(STDEV(E7:E12)/AVERAGE(E7:E12)*100,2),""))
A9: IMP-01 | B9: LOQ | C9: 3 | G9: =IFERROR(ROUND(F9/VLOOKUP(A9,'杂质清单'!$A$4:$F$13,6,FALSE),2),"") | H9: =IFERROR(ROUND(G9/VLOOKUP(A9,'杂质清单'!$A$4:$F$13,4,FALSE)*100,2),"") | I9: =IF(B9<>"LOQ","",IFERROR(ROUND(STDEV(E7:E12)/AVERAGE(E7:E12)*100,2),""))
A10: IMP-01 | B10: LOQ | C10: 4 | G10: =IFERROR(ROUND(F10/VLOOKUP(A10,'杂质清单'!$A$4:$F$13,6,FALSE),2),"") | H10: =IFERROR(ROUND(G10/VLOOKUP(A10,'杂质清单'!$A$4:$F$13,4,FALSE)*100,2),"") | I10: =IF(B10<>"LOQ","",IFERROR(ROUND(STDEV(E7:E12)/AVERAGE(E7:E12)*100,2),""))
A11: IMP-01 | B11: LOQ | C11: 5 | G11: =IFERROR(ROUND(F11/VLOOKUP(A11,'杂质清单'!$A$4:$F$13,6,FALSE),2),"") | H11: =IFERROR(ROUND(G11/VLOOKUP(A11,'杂质清单'!$A$4:$F$13,4,FALSE)*100,2),"") | I11: =IF(B11<>"LOQ","",IFERROR(ROUND(STDEV(E7:E12)/AVERAGE(E7:E12)*100,2),""))
A12: IMP-01 | B12: LOQ | C12: 6 | G12: =IFERROR(ROUND(F12/VLOOKUP(A12,'杂质清单'!$A$4:$F$13,6,FALSE),2),"") | H12: =IFERROR(ROUND(G12/VLOOKUP(A12,'杂质清单'!$A$4:$F$13,4,FALSE)*100,2),"") | I12: =IF(B12<>"LOQ","",IFERROR(ROUND(STDEV(E7:E12)/AVERAGE(E7:E12)*100,2),""))
A13: IMP-02 | B13: LOD | C13: 1 | G13: =IFERROR(ROUND(F13/VLOOKUP(A13,'杂质清单'!$A$4:$F$13,6,FALSE),2),"") | H13: =IFERROR(ROUND(G13/VLOOKUP(A13,'杂质清单'!$A$4:$F$13,4,FALSE)*100,2),"") | I13: =IF(B13<>"LOQ","",IFERROR(ROUND(STDEV(E16:E21)/AVERAGE(E16:E21)*100,2),""))
A14: IMP-02 | B14: LOD | C14: 2 | G14: =IFERROR(ROUND(F14/VLOOKUP(A14,'杂质清单'!$A$4:$F$13,6,FALSE),2),"") | H14: =IFERROR(ROUND(G14/VLOOKUP(A14,'杂质清单'!$A$4:$F$13,4,FALSE)*100,2),"") | I14: =IF(B14<>"LOQ","",IFERROR(ROUND(STDEV(E16:E21)/AVERAGE(E16:E21)*100,2),""))
A15: IMP-02 | B15: LOD | C15: 3 | G15: =IFERROR(ROUND(F15/VLOOKUP(A15,'杂质清单'!$A$4:$F$13,6,FALSE),2),"") | H15: =IFERROR(ROUND(G15/VLOOKUP(A15,'杂质清单'!$A$4:$F$13,4,FALSE)*100,2),"") | I15: =IF(B15<>"LOQ","",IFERROR(ROUND(STDEV(E16:E21)/AVERAGE(E16:E21)*100,2),""))
A16: IMP-02 | B16: LOQ | C16: 1 | G16: =IFERROR(ROUND(F16/VLOOKUP(A16,'杂质清单'!$A$4:$F$13,6,FALSE),2),"") | H16: =IFERROR(ROUND(G16/VLOOKUP(A16,'杂质清单'!$A$4:$F$13,4,FALSE)*100,2),"") | I16: =IF(B16<>"LOQ","",IFERROR(ROUND(STDEV(E16:E21)/AVERAGE(E16:E21)*100,2),""))
A17: IMP-02 | B17: LOQ | C17: 2 | G17: =IFERROR(ROUND(F17/VLOOKUP(A17,'杂质清单'!$A$4:$F$13,6,FALSE),2),"") | H17: =IFERROR(ROUND(G17/VLOOKUP(A17,'杂质清单'!$A$4:$F$13,4,FALSE)*100,2),"") | I17: =IF(B17<>"LOQ","",IFERROR(ROUND(STDEV(E16:E21)/AVERAGE(E16:E21)*100,2),""))
A18: IMP-02 | B18: LOQ | C18: 3 | G18: =IFERROR(ROUND(F18/VLOOKUP(A18,'杂质清单'!$A$4:$F$13,6,FALSE),2),"") | H18: =IFERROR(ROUND(G18/VLOOKUP(A18,'杂质清单'!$A$4:$F$13,4,FALSE)*100,2),"") | I18: =IF(B18<>"LOQ","",IFERROR(ROUND(STDEV(E16:E21)/AVERAGE(E16:E21)*100,2),""))
A19: IMP-02 | B19: LOQ | C19: 4 | G19: =IFERROR(ROUND(F19/VLOOKUP(A19,'杂质清单'!$A$4:$F$13,6,FALSE),2),"") | H19: =IFERROR(ROUND(G19/VLOOKUP(A19,'杂质清单'!$A$4:$F$13,4,FALSE)*100,2),"") | I19: =IF(B19<>"LOQ","",IFERROR(ROUND(STDEV(E16:E21)/AVERAGE(E16:E21)*100,2),""))
A20: IMP-02 | B20: LOQ | C20: 5 | G20: =IFERROR(ROUND(F20/VLOOKUP(A20,'杂质清单'!$A$4:$F$13,6,FALSE),2),"") | H20: =IFERROR(ROUND(G20/VLOOKUP(A20,'杂质清单'!$A$4:$F$13,4,FALSE)*100,2),"") | I20: =IF(B20<>"LOQ","",IFERROR(ROUND(STDEV(E16:E21)/AVERAGE(E16:E21)*100,2),""))
A21: IMP-02 | B21: LOQ | C21: 6 | G21: =IFERROR(ROUND(F21/VLOOKUP(A21,'杂质清单'!$A$4:$F$13,6,FALSE),2),"") | H21: =IFERROR(ROUND(G21/VLOOKUP(A21,'杂质清单'!$A$4:$F$13,4,FALSE)*100,2),"") | I21: =IF(B21<>"LOQ","",IFERROR(ROUND(STDEV(E16:E21)/AVERAGE(E16:E21)*100,2),""))
A22: IMP-03 | B22: LOD | C22: 1 | G22: =IFERROR(ROUND(F22/VLOOKUP(A22,'杂质清单'!$A$4:$F$13,6,FALSE),2),"") | H22: =IFERROR(ROUND(G22/VLOOKUP(A22,'杂质清单'!$A$4:$F$13,4,FALSE)*100,2),"") | I22: =IF(B22<>"LOQ","",IFERROR(ROUND(STDEV(E25:E30)/AVERAGE(E25:E30)*100,2),""))
A23: IMP-03 | B23: LOD | C23: 2 | G23: =IFERROR(ROUND(F23/VLOOKUP(A23,'杂质清单'!$A$4:$F$13,6,FALSE),2),"") | H23: =IFERROR(ROUND(G23/VLOOKUP(A23,'杂质清单'!$A$4:$F$13,4,FALSE)*100,2),"") | I23: =IF(B23<>"LOQ","",IFERROR(ROUND(STDEV(E25:E30)/AVERAGE(E25:E30)*100,2),""))
A24: IMP-03 | B24: LOD | C24: 3 | G24: =IFERROR(ROUND(F24/VLOOKUP(A24,'杂质清单'!$A$4:$F$13,6,FALSE),2),"") | H24: =IFERROR(ROUND(G24/VLOOKUP(A24,'杂质清单'!$A$4:$F$13,4,FALSE)*100,2),"") | I24: =IF(B24<>"LOQ","",IFERROR(ROUND(STDEV(E25:E30)/AVERAGE(E25:E30)*100,2),""))
A25: IMP-03 | B25: LOQ | C25: 1 | G25: =IFERROR(ROUND(F25/VLOOKUP(A25,'杂质清单'!$A$4:$F$13,6,FALSE),2),"") | H25: =IFERROR(ROUND(G25/VLOOKUP(A25,'杂质清单'!$A$4:$F$13,4,FALSE)*100,2),"") | I25: =IF(B25<>"LOQ","",IFERROR(ROUND(STDEV(E25:E30)/AVERAGE(E25:E30)*100,2),""))
A26: IMP-03 | B26: LOQ | C26: 2 | G26: =IFERROR(ROUND(F26/VLOOKUP(A26,'杂质清单'!$A$4:$F$13,6,FALSE),2),"") | H26: =IFERROR(ROUND(G26/VLOOKUP(A26,'杂质清单'!$A$4:$F$13,4,FALSE)*100,2),"") | I26: =IF(B26<>"LOQ","",IFERROR(ROUND(STDEV(E25:E30)/AVERAGE(E25:E30)*100,2),""))
A27: IMP-03 | B27: LOQ | C27: 3 | G27: =IFERROR(ROUND(F27/VLOOKUP(A27,'杂质清单'!$A$4:$F$13,6,FALSE),2),"") | H27: =IFERROR(ROUND(G27/VLOOKUP(A27,'杂质清单'!$A$4:$F$13,4,FALSE)*100,2),"") | I27: =IF(B27<>"LOQ","",IFERROR(ROUND(STDEV(E25:E30)/AVERAGE(E25:E30)*100,2),""))
A28: IMP-03 | B28: LOQ | C28: 4 | G28: =IFERROR(ROUND(F28/VLOOKUP(A28,'杂质清单'!$A$4:$F$13,6,FALSE),2),"") | H28: =IFERROR(ROUND(G28/VLOOKUP(A28,'杂质清单'!$A$4:$F$13,4,FALSE)*100,2),"") | I28: =IF(B28<>"LOQ","",IFERROR(ROUND(STDEV(E25:E30)/AVERAGE(E25:E30)*100,2),""))
A29: IMP-03 | B29: LOQ | C29: 5 | G29: =IFERROR(ROUND(F29/VLOOKUP(A29,'杂质清单'!$A$4:$F$13,6,FALSE),2),"") | H29: =IFERROR(ROUND(G29/VLOOKUP(A29,'杂质清单'!$A$4:$F$13,4,FALSE)*100,2),"") | I29: =IF(B29<>"LOQ","",IFERROR(ROUND(STDEV(E25:E30)/AVERAGE(E25:E30)*100,2),""))
A30: IMP-03 | B30: LOQ | C30: 6 | G30: =IFERROR(ROUND(F30/VLOOKUP(A30,'杂质清单'!$A$4:$F$13,6,FALSE),2),"") | H30: =IFERROR(ROUND(G30/VLOOKUP(A30,'杂质清单'!$A$4:$F$13,4,FALSE)*100,2),"") | I30: =IF(B30<>"LOQ","",IFERROR(ROUND(STDEV(E25:E30)/AVERAGE(E25:E30)*100,2),""))
A31: IMP-04 | B31: LOD | C31: 1 | G31: =IFERROR(ROUND(F31/VLOOKUP(A31,'杂质清单'!$A$4:$F$13,6,FALSE),2),"") | H31: =IFERROR(ROUND(G31/VLOOKUP(A31,'杂质清单'!$A$4:$F$13,4,FALSE)*100,2),"") | I31: =IF(B31<>"LOQ","",IFERROR(ROUND(STDEV(E34:E39)/AVERAGE(E34:E39)*100,2),""))
A32: IMP-04 | B32: LOD | C32: 2 | G32: =IFERROR(ROUND(F32/VLOOKUP(A32,'杂质清单'!$A$4:$F$13,6,FALSE),2),"") | H32: =IFERROR(ROUND(G32/VLOOKUP(A32,'杂质清单'!$A$4:$F$13,4,FALSE)*100,2),"") | I32: =IF(B32<>"LOQ","",IFERROR(ROUND(STDEV(E34:E39)/AVERAGE(E34:E39)*100,2),""))
A33: IMP-04 | B33: LOD | C33: 3 | G33: =IFERROR(ROUND(F33/VLOOKUP(A33,'杂质清单'!$A$4:$F$13,6,FALSE),2),"") | H33: =IFERROR(ROUND(G33/VLOOKUP(A33,'杂质清单'!$A$4:$F$13,4,FALSE)*100,2),"") | I33: =IF(B33<>"LOQ","",IFERROR(ROUND(STDEV(E34:E39)/AVERAGE(E34:E39)*100,2),""))
A34: IMP-04 | B34: LOQ | C34: 1 | G34: =IFERROR(ROUND(F34/VLOOKUP(A34,'杂质清单'!$A$4:$F$13,6,FALSE),2),"") | H34: =IFERROR(ROUND(G34/VLOOKUP(A34,'杂质清单'!$A$4:$F$13,4,FALSE)*100,2),"") | I34: =IF(B34<>"LOQ","",IFERROR(ROUND(STDEV(E34:E39)/AVERAGE(E34:E39)*100,2),""))
A35: IMP-04 | B35: LOQ | C35: 2 | G35: =IFERROR(ROUND(F35/VLOOKUP(A35,'杂质清单'!$A$4:$F$13,6,FALSE),2),"") | H35: =IFERROR(ROUND(G35/VLOOKUP(A35,'杂质清单'!$A$4:$F$13,4,FALSE)*100,2),"") | I35: =IF(B35<>"LOQ","",IFERROR(ROUND(STDEV(E34:E39)/AVERAGE(E34:E39)*100,2),""))
A36: IMP-04 | B36: LOQ | C36: 3 | G36: =IFERROR(ROUND(F36/VLOOKUP(A36,'杂质清单'!$A$4:$F$13,6,FALSE),2),"") | H36: =IFERROR(ROUND(G36/VLOOKUP(A36,'杂质清单'!$A$4:$F$13,4,FALSE)*100,2),"") | I36: =IF(B36<>"LOQ","",IFERROR(ROUND(STDEV(E34:E39)/AVERAGE(E34:E39)*100,2),""))
A37: IMP-04 | B37: LOQ | C37: 4 | G37: =IFERROR(ROUND(F37/VLOOKUP(A37,'杂质清单'!$A$4:$F$13,6,FALSE),2),"") | H37: =IFERROR(ROUND(G37/VLOOKUP(A37,'杂质清单'!$A$4:$F$13,4,FALSE)*100,2),"") | I37: =IF(B37<>"LOQ","",IFERROR(ROUND(STDEV(E34:E39)/AVERAGE(E34:E39)*100,2),""))
A38: IMP-04 | B38: LOQ | C38: 5 | G38: =IFERROR(ROUND(F38/VLOOKUP(A38,'杂质清单'!$A$4:$F$13,6,FALSE),2),"") | H38: =IFERROR(ROUND(G38/VLOOKUP(A38,'杂质清单'!$A$4:$F$13,4,FALSE)*100,2),"") | I38: =IF(B38<>"LOQ","",IFERROR(ROUND(STDEV(E34:E39)/AVERAGE(E34:E39)*100,2),""))
A39: IMP-04 | B39: LOQ | C39: 6 | G39: =IFERROR(ROUND(F39/VLOOKUP(A39,'杂质清单'!$A$4:$F$13,6,FALSE),2),"") | H39: =IFERROR(ROUND(G39/VLOOKUP(A39,'杂质清单'!$A$4:$F$13,4,FALSE)*100,2),"") | I39: =IF(B39<>"LOQ","",IFERROR(ROUND(STDEV(E34:E39)/AVERAGE(E34:E39)*100,2),""))
A40: IMP-05 | B40: LOD | C40: 1 | G40: =IFERROR(ROUND(F40/VLOOKUP(A40,'杂质清单'!$A$4:$F$13,6,FALSE),2),"") | H40: =IFERROR(ROUND(G40/VLOOKUP(A40,'杂质清单'!$A$4:$F$13,4,FALSE)*100,2),"") | I40: =IF(B40<>"LOQ","",IFERROR(ROUND(STDEV(E43:E48)/AVERAGE(E43:E48)*100,2),""))
...

Sheet 线性溶液数值
A1: 线性溶液数值
A2: impurity_id | B2: run_type | C2: solution_name | D2: stock_concentration | E2: aliquot_volume | F2: final_volume | G2: theoretical_concentration | H2: limit_percentage
A3: 杂质编号 | B3: 线性批次 | C3: 溶液名称 | D3: 中间贮备液浓度 | E3: 量取体积（ml） | F3: 定容至（ml） | G3: 目标溶液理论浓度 | H3: 占限度浓度百分比（%）
A4: IMP-01 | B4: INITIAL | C4: C1 | G4: =IFERROR(D4*E4/F4,"") | H4: =IFERROR(G4/VLOOKUP(A4,'杂质清单'!$A$4:$F$13,5,FALSE)*100,"")
A5: IMP-01 | B5: INITIAL | C5: C2 | G5: =IFERROR(D5*E5/F5,"") | H5: =IFERROR(G5/VLOOKUP(A5,'杂质清单'!$A$4:$F$13,5,FALSE)*100,"")
A6: IMP-01 | B6: INITIAL | C6: C3 | G6: =IFERROR(D6*E6/F6,"") | H6: =IFERROR(G6/VLOOKUP(A6,'杂质清单'!$A$4:$F$13,5,FALSE)*100,"")
A7: IMP-01 | B7: INITIAL | C7: C4 | G7: =IFERROR(D7*E7/F7,"") | H7: =IFERROR(G7/VLOOKUP(A7,'杂质清单'!$A$4:$F$13,5,FALSE)*100,"")
A8: IMP-01 | B8: INITIAL | C8: C5 | G8: =IFERROR(D8*E8/F8,"") | H8: =IFERROR(G8/VLOOKUP(A8,'杂质清单'!$A$4:$F$13,5,FALSE)*100,"")
A9: IMP-01 | B9: INTERMEDIATE | C9: C1 | G9: =IFERROR(D9*E9/F9,"") | H9: =IFERROR(G9/VLOOKUP(A9,'杂质清单'!$A$4:$F$13,5,FALSE)*100,"")
A10: IMP-01 | B10: INTERMEDIATE | C10: C2 | G10: =IFERROR(D10*E10/F10,"") | H10: =IFERROR(G10/VLOOKUP(A10,'杂质清单'!$A$4:$F$13,5,FALSE)*100,"")
A11: IMP-01 | B11: INTERMEDIATE | C11: C3 | G11: =IFERROR(D11*E11/F11,"") | H11: =IFERROR(G11/VLOOKUP(A11,'杂质清单'!$A$4:$F$13,5,FALSE)*100,"")
A12: IMP-01 | B12: INTERMEDIATE | C12: C4 | G12: =IFERROR(D12*E12/F12,"") | H12: =IFERROR(G12/VLOOKUP(A12,'杂质清单'!$A$4:$F$13,5,FALSE)*100,"")
A13: IMP-01 | B13: INTERMEDIATE | C13: C5 | G13: =IFERROR(D13*E13/F13,"") | H13: =IFERROR(G13/VLOOKUP(A13,'杂质清单'!$A$4:$F$13,5,FALSE)*100,"")
A14: IMP-02 | B14: INITIAL | C14: C1 | G14: =IFERROR(D14*E14/F14,"") | H14: =IFERROR(G14/VLOOKUP(A14,'杂质清单'!$A$4:$F$13,5,FALSE)*100,"")
A15: IMP-02 | B15: INITIAL | C15: C2 | G15: =IFERROR(D15*E15/F15,"") | H15: =IFERROR(G15/VLOOKUP(A15,'杂质清单'!$A$4:$F$13,5,FALSE)*100,"")
... A103: IMP-10 | B103: INTERMEDIATE | C103: C5 | G103: =IFERROR(D103*E103/F103,"") | H103: =IFERROR(G103/VLOOKUP(A103,'杂质清单'!$A$4:$F$13,5,FALSE)*100,"")

Sheet 线性与范围结果
A1: 线性与范围结果
A2: impurity_id | B2: run_type | C2: level | D2: actual_concentration | E2: peak_area | F2: predicted_peak_area | G2: residual | H2: relative_residual | I2: slope | J2: intercept | K2: correlation_coefficient | L2: intercept_ratio
A3: 杂质编号 | B3: 线性批次 | C3: 浓度级别 | D3: 实际浓度（ng/ml） | E3: 峰面积 | F3: 预测峰面积 | G3: 残差 | H3: 相对残差（%） | I3: 斜率 | J3: 截距 | K3: 相关系数r | L3: 截距/100%峰面积（%）
A4: IMP-01 | B4: INITIAL | C4: C1 | F4: =IFERROR(I4*D4+J4,"") | G4: =IFERROR(E4-F4,"") | H4: =IFERROR(ROUND(G4/F4*100,2),"") | I4: =IFERROR(SLOPE(E4:E8,D4:D8),"") | J4: =IFERROR(INTERCEPT(E4:E8,D4:D8),"") | K4: =IFERROR(CORREL(E4:E8,D4:D8),"") | L4: =IFERROR(ROUND(J4/E6*100,2),"")
A5: IMP-01 | B5: INITIAL | C5: C2 | F5: =IFERROR(I5*D5+J5,"") | G5: =IFERROR(E5-F5,"") | H5: =IFERROR(ROUND(G5/F5*100,2),"") | I5: =IFERROR(SLOPE(E4:E8,D4:D8),"") | J5: =IFERROR(INTERCEPT(E4:E8,D4:D8),"") | K5: =IFERROR(CORREL(E4:E8,D4:D8),"") | L5: =IFERROR(ROUND(J5/E6*100,2),"")
A6: IMP-01 | B6: INITIAL | C6: C3 | F6: =IFERROR(I6*D6+J6,"") | G6: =IFERROR(E6-F6,"") | H6: =IFERROR(ROUND(G6/F6*100,2),"") | I6: =IFERROR(SLOPE(E4:E8,D4:D8),"") | J6: =IFERROR(INTERCEPT(E4:E8,D4:D8),"") | K6: =IFERROR(CORREL(E4:E8,D4:D8),"") | L6: =IFERROR(ROUND(J6/E6*100,2),"")
A7: IMP-01 | B7: INITIAL | C7: C4 | F7: =IFERROR(I7*D7+J7,"") | G7: =IFERROR(E7-F7,"") | H7: =IFERROR(ROUND(G7/F7*100,2),"") | I7: =IFERROR(SLOPE(E4:E8,D4:D8),"") | J7: =IFERROR(INTERCEPT(E4:E8,D4:D8),"") | K7: =IFERROR(CORREL(E4:E8,D4:D8),"") | L7: =IFERROR(ROUND(J7/E6*100,2),"")
A8: IMP-01 | B8: INITIAL | C8: C5 | F8: =IFERROR(I8*D8+J8,"") | G8: =IFERROR(E8-F8,"") | H8: =IFERROR(ROUND(G8/F8*100,2),"") | I8: =IFERROR(SLOPE(E4:E8,D4:D8),"") | J8: =IFERROR(INTERCEPT(E4:E8,D4:D8),"") | K8: =IFERROR(CORREL(E4:E8,D4:D8),"") | L8: =IFERROR(ROUND(J8/E6*100,2),"")
A9: IMP-01 | B9: INTERMEDIATE | C9: C1 | F9: =IFERROR(I9*D9+J9,"") | G9: =IFERROR(E9-F9,"") | H9: =IFERROR(ROUND(G9/F9*100,2),"") | I9: =IFERROR(SLOPE(E9:E13,D9:D13),"") | J9: =IFERROR(INTERCEPT(E9:E13,D9:D13),"") | K9: =IFERROR(CORREL(E9:E13,D9:D13),"") | L9: =IFERROR(ROUND(J9/E11*100,2),"")
A10: IMP-01 | B10: INTERMEDIATE | C10: C2 | F10: =IFERROR(I10*D10+J10,"") | G10: =IFERROR(E10-F10,"") | H10: =IFERROR(ROUND(G10/F10*100,2),"") | I10: =IFERROR(SLOPE(E9:E13,D9:D13),"") | J10: =IFERROR(INTERCEPT(E9:E13,D9:D13),"") | K10: =IFERROR(CORREL(E9:E13,D9:D13),"") | L10: =IFERROR(ROUND(J10/E11*100,2),"")
A11: IMP-01 | B11: INTERMEDIATE | C11: C3 | F11: =IFERROR(I11*D11+J11,"") | G11: =IFERROR(E11-F11,"") | H11: =IFERROR(ROUND(G11/F11*100,2),"") | I11: =IFERROR(SLOPE(E9:E13,D9:D13),"") | J11: =IFERROR(INTERCEPT(E9:E13,D9:D13),"") | K11: =IFERROR(CORREL(E9:E13,D9:D13),"") | L11: =IFERROR(ROUND(J11/E11*100,2),"")
A12: IMP-01 | B12: INTERMEDIATE | C12: C4 | F12: =IFERROR(I12*D12+J12,"") | G12: =IFERROR(E12-F12,"") | H12: =IFERROR(ROUND(G12/F12*100,2),"") | I12: =IFERROR(SLOPE(E9:E13,D9:D13),"") | J12: =IFERROR(INTERCEPT(E9:E13,D9:D13),"") | K12: =IFERROR(CORREL(E9:E13,D9:D13),"") | L12: =IFERROR(ROUND(J12/E11*100,2),"")
A13: IMP-01 | B13: INTERMEDIATE | C13: C5 | F13: =IFERROR(I13*D13+J13,"") | G13: =IFERROR(E13-F13,"") | H13: =IFERROR(ROUND(G13/F13*100,2),"") | I13: =IFERROR(SLOPE(E9:E13,D9:D13),"") | J13: =IFERROR(INTERCEPT(E9:E13,D9:D13),"") | K13: =IFERROR(CORREL(E9:E13,D9:D13),"") | L13: =IFERROR(ROUND(J13/E11*100,2),"")
A14: IMP-02 | B14: INITIAL | C14: C1 | F14: =IFERROR(I14*D14+J14,"") | G14: =IFERROR(E14-F14,"") | H14: =IFERROR(ROUND(G14/F14*100,2),"") | I14: =IFERROR(SLOPE(E14:E18,D14:D18),"") | J14: =IFERROR(INTERCEPT(E14:E18,D14:D18),"") | K14: =IFERROR(CORREL(E14:E18,D14:D18),"") | L14: =IFERROR(ROUND(J14/E16*100,2),"")
A15: IMP-02 | B15: INITIAL | C15: C2 | F15: =IFERROR(I15*D15+J15,"") | G15: =IFERROR(E15-F15,"") | H15: =IFERROR(ROUND(G15/F15*100,2),"") | I15: =IFERROR(SLOPE(E14:E18,D14:D18),"") | J15: =IFERROR(INTERCEPT(E14:E18,D14:D18),"") | K15: =IFERROR(CORREL(E14:E18,D14:D18),"") | L15: =IFERROR(ROUND(J15/E16*100,2),"")
A16: IMP-02 | B16: INITIAL | C16: C3 | F16: =IFERROR(I16*D16+J16,"") | G16: =IFERROR(E16-F16,"") | H16: =IFERROR(ROUND(G16/F16*100,2),"") | I16: =IFERROR(SLOPE(E14:E18,D14:D18),"") | J16: =IFERROR(INTERCEPT(E14:E18,D14:D18),"") | K16: =IFERROR(CORREL(E14:E18,D14:D18),"") | L16: =IFERROR(ROUND(J16/E16*100,2),"")
A17: IMP-02 | B17: INITIAL | C17: C4 | F17: =IFERROR(I17*D17+J17,"") | G17: =IFERROR(E17-F17,"") | H17: =IFERROR(ROUND(G17/F17*100,2),"") | I17: =IFERROR(SLOPE(E14:E18,D14:D18),"") | J17: =IFERROR(INTERCEPT(E14:E18,D14:D18),"") | K17: =IFERROR(CORREL(E14:E18,D14:D18),"") | L17: =IFERROR(ROUND(J17/E16*100,2),"")
A18: IMP-02 | B18: INITIAL | C18: C5 | F18: =IFERROR(I18*D18+J18,"") | G18: =IFERROR(E18-F18,"") | H18: =IFERROR(ROUND(G18/F18*100,2),"") | I18: =IFERROR(SLOPE(E14:E18,D14:D18),"") | J18: =IFERROR(INTERCEPT(E14:E18,D14:D18),"") | K18: =IFERROR(CORREL(E14:E18,D14:D18),"") | L18: =IFERROR(ROUND(J18/E16*100,2),"")
A19: IMP-02 | B19: INTERMEDIATE | C19: C1 | F19: =IFERROR(I19*D19+J19,"") | G19: =IFERROR(E19-F19,"") | H19: =IFERROR(ROUND(G19/F19*100,2),"") | I19: =IFERROR(SLOPE(E19:E23,D19:D23),"") | J19: =IFERROR(INTERCEPT(E19:E23,D19:D23),"") | K19: =IFERROR(CORREL(E19:E23,D19:D23),"") | L19: =IFERROR(ROUND(J19/E21*100,2),"")
A20: IMP-02 | B20: INTERMEDIATE | C20: C2 | F20: =IFERROR(I20*D20+J20,"") | G20: =IFERROR(E20-F20,"") | H20: =IFERROR(ROUND(G20/F20*100,2),"") | I20: =IFERROR(SLOPE(E19:E23,D19:D23),"") | J20: =IFERROR(INTERCEPT(E19:E23,D19:D23),"") | K20: =IFERROR(CORREL(E19:E23,D19:D23),"") | L20: =IFERROR(ROUND(J20/E21*100,2),"")
A21: IMP-02 | B21: INTERMEDIATE | C21: C3 | F21: =IFERROR(I21*D21+J21,"") | G21: =IFERROR(E21-F21,"") | H21: =IFERROR(ROUND(G21/F21*100,2),"") | I21: =IFERROR(SLOPE(E19:E23,D19:D23),"") | J21: =IFERROR(INTERCEPT(E19:E23,D19:D23),"") | K21: =IFERROR(CORREL(E19:E23,D19:D23),"") | L21: =IFERROR(ROUND(J21/E21*100,2),"")
A22: IMP-02 | B22: INTERMEDIATE | C22: C4 | F22: =IFERROR(I22*D22+J22,"") | G22: =IFERROR(E22-F22,"") | H22: =IFERROR(ROUND(G22/F22*100,2),"") | I22: =IFERROR(SLOPE(E19:E23,D19:D23),"") | J22: =IFERROR(INTERCEPT(E19:E23,D19:D23),"") | K22: =IFERROR(CORREL(E19:E23,D19:D23),"") | L22: =IFERROR(ROUND(J22/E21*100,2),"")
A23: IMP-02 | B23: INTERMEDIATE | C23: C5 | F23: =IFERROR(I23*D23+J23,"") | G23: =IFERROR(E23-F23,"") | H23: =IFERROR(ROUND(G23/F23*100,2),"") | I23: =IFERROR(SLOPE(E19:E23,D19:D23),"") | J23: =IFERROR(INTERCEPT(E19:E23,D19:D23),"") | K23: =IFERROR(CORREL(E19:E23,D19:D23),"") | L23: =IFERROR(ROUND(J23/E21*100,2),"")
A24: IMP-03 | B24: INITIAL | C24: C1 | F24: =IFERROR(I24*D24+J24,"") | G24: =IFERROR(E24-F24,"") | H24: =IFERROR(ROUND(G24/F24*100,2),"") | I24: =IFERROR(SLOPE(E24:E28,D24:D28),"") | J24: =IFERROR(INTERCEPT(E24:E28,D24:D28),"") | K24: =IFERROR(CORREL(E24:E28,D24:D28),"") | L24: =IFERROR(ROUND(J24/E26*100,2),"")
A25: IMP-03 | B25: INITIAL | C25: C2 | F25: =IFERROR(I25*D25+J25,"") | G25: =IFERROR(E25-F25,"") | H25: =IFERROR(ROUND(G25/F25*100,2),"") | I25: =IFERROR(SLOPE(E24:E28,D24:D28),"") | J25: =IFERROR(INTERCEPT(E24:E28,D24:D28),"") | K25: =IFERROR(CORREL(E24:E28,D24:D28),"") | L25: =IFERROR(ROUND(J25/E26*100,2),"")
A26: IMP-03 | B26: INITIAL | C26: C3 | F26: =IFERROR(I26*D26+J26,"") | G26: =IFERROR(E26-F26,"") | H26: =IFERROR(ROUND(G26/F26*100,2),"") | I26: =IFERROR(SLOPE(E24:E28,D24:D28),"") | J26: =IFERROR(INTERCEPT(E24:E28,D24:D28),"") | K26: =IFERROR(CORREL(E24:E28,D24:D28),"") | L26: =IFERROR(ROUND(J26/E26*100,2),"")
A27: IMP-03 | B27: INITIAL | C27: C4 | F27: =IFERROR(I27*D27+J27,"") | G27: =IFERROR(E27-F27,"") | H27: =IFERROR(ROUND(G27/F27*100,2),"") | I27: =IFERROR(SLOPE(E24:E28,D24:D28),"") | J27: =IFERROR(INTERCEPT(E24:E28,D24:D28),"") | K27: =IFERROR(CORREL(E24:E28,D24:D28),"") | L27: =IFERROR(ROUND(J27/E26*100,2),"")
A28: IMP-03 | B28: INITIAL | C28: C5 | F28: =IFERROR(I28*D28+J28,"") | G28: =IFERROR(E28-F28,"") | H28: =IFERROR(ROUND(G28/F28*100,2),"") | I28: =IFERROR(SLOPE(E24:E28,D24:D28),"") | J28: =IFERROR(INTERCEPT(E24:E28,D24:D28),"") | K28: =IFERROR(CORREL(E24:E28,D24:D28),"") | L28: =IFERROR(ROUND(J28/E26*100,2),"")
A29: IMP-03 | B29: INTERMEDIATE | C29: C1 | F29: =IFERROR(I29*D29+J29,"") | G29: =IFERROR(E29-F29,"") | H29: =IFERROR(ROUND(G29/F29*100,2),"") | I29: =IFERROR(SLOPE(E29:E33,D29:D33),"") | J29: =IFERROR(INTERCEPT(E29:E33,D29:D33),"") | K29: =IFERROR(CORREL(E29:E33,D29:D33),"") | L29: =IFERROR(ROUND(J29/E31*100,2),"")
A30: IMP-03 | B30: INTERMEDIATE | C30: C2 | F30: =IFERROR(I30*D30+J30,"") | G30: =IFERROR(E30-F30,"") | H30: =IFERROR(ROUND(G30/F30*100,2),"") | I30: =IFERROR(SLOPE(E29:E33,D29:D33),"") | J30: =IFERROR(INTERCEPT(E29:E33,D29:D33),"") | K30: =IFERROR(CORREL(E29:E33,D29:D33),"") | L30: =IFERROR(ROUND(J30/E31*100,2),"")
A31: IMP-03 | B31: INTERMEDIATE | C31: C3 | F31: =IFERROR(I31*D31+J31,"") | G31: =IFERROR(E31-F31,"") | H31: =IFERROR(ROUND(G31/F31*100,2),"") | I31: =IFERROR(SLOPE(E29:E33,D29:D33),"") | J31: =IFERROR(INTERCEPT(E29:E33,D29:D33),"") | K31: =IFERROR(CORREL(E29:E33,D29:D33),"") | L31: =IFERROR(ROUND(J31/E31*100,2),"")
A32: IMP-03 | B32: INTERMEDIATE | C32: C4 | F32: =IFERROR(I32*D32+J32,"") | G32: =IFERROR(E32-F32,"") | H32: =IFERROR(ROUND(G32/F32*100,2),"") | I32: =IFERROR(SLOPE(E29:E33,D29:D33),"") | J32: =IFERROR(INTERCEPT(E29:E33,D29:D33),"") | K32: =IFERROR(CORREL(E29:E33,D29:D33),"") | L32: =IFERROR(ROUND(J32/E31*100,2),"")
A33: IMP-03 | B33: INTERMEDIATE | C33: C5 | F33: =IFERROR(I33*D33+J33,"") | G33: =IFERROR(E33-F33,"") | H33: =IFERROR(ROUND(G33/F33*100,2),"") | I33: =IFERROR(SLOPE(E29:E33,D29:D33),"") | J33: =IFERROR(INTERCEPT(E29:E33,D29:D33),"") | K33: =IFERROR(CORREL(E29:E33,D29:D33),"") | L33: =IFERROR(ROUND(J33/E31*100,2),"")
A34: IMP-04 | B34: INITIAL | C34: C1 | F34: =IFERROR(I34*D34+J34,"") | G34: =IFERROR(E34-F34,"") | H34: =IFERROR(ROUND(G34/F34*100,2),"") | I34: =IFERROR(SLOPE(E34:E38,D34:D38),"") | J34: =IFERROR(INTERCEPT(E34:E38,D34:D38),"") | K34: =IFERROR(CORREL(E34:E38,D34:D38),"") | L34: =IFERROR(ROUND(J34/E36*100,2),"")
A35: IMP-04 | B35: INITIAL | C35: C2 | F35: =IFERROR(I35*D35+J35,"") | G35: =IFERROR(E35-F35,"") | H35: =IFERROR(ROUND(G35/F35*100,2),"") | I35: =IFERROR(SLOPE(E34:E38,D34:D38),"") | J35: =IFERROR(INTERCEPT(E34:E38,D34:D38),"") | K35: =IFERROR(CORREL(E34:E38,D34:D38),"") | L35: =IFERROR(ROUND(J35/E36*100,2),"")
A36: IMP-04 | B36: INITIAL | C36: C3 | F36: =IFERROR(I36*D36+J36,"") | G36: =IFERROR(E36-F36,"") | H36: =IFERROR(ROUND(G36/F36*100,2),"") | I36: =IFERROR(SLOPE(E34:E38,D34:D38),"") | J36: =IFERROR(INTERCEPT(E34:E38,D34:D38),"") | K36: =IFERROR(CORREL(E34:E38,D34:D38),"") | L36: =IFERROR(ROUND(J36/E36*100,2),"")
A37: IMP-04 | B37: INITIAL | C37: C4 | F37: =IFERROR(I37*D37+J37,"") | G37: =IFERROR(E37-F37,"") | H37: =IFERROR(ROUND(G37/F37*100,2),"") | I37: =IFERROR(SLOPE(E34:E38,D34:D38),"") | J37: =IFERROR(INTERCEPT(E34:E38,D34:D38),"") | K37: =IFERROR(CORREL(E34:E38,D34:D38),"") | L37: =IFERROR(ROUND(J37/E36*100,2),"")
A38: IMP-04 | B38: INITIAL | C38: C5 | F38: =IFERROR(I38*D38+J38,"") | G38: =IFERROR(E38-F38,"") | H38: =IFERROR(ROUND(G38/F38*100,2),"") | I38: =IFERROR(SLOPE(E34:E38,D34:D38),"") | J38: =IFERROR(INTERCEPT(E34:E38,D34:D38),"") | K38: =IFERROR(CORREL(E34:E38,D34:D38),"") | L38: =IFERROR(ROUND(J38/E36*100,2),"")
A39: IMP-04 | B39: INTERMEDIATE | C39: C1 | F39: =IFERROR(I39*D39+J39,"") | G39: =IFERROR(E39-F39,"") | H39: =IFERROR(ROUND(G39/F39*100,2),"") | I39: =IFERROR(SLOPE(E39:E43,D39:D43),"") | J39: =IFERROR(INTERCEPT(E39:E43,D39:D43),"") | K39: =IFERROR(CORREL(E39:E43,D39:D43),"") | L39: =IFERROR(ROUND(J39/E41*100,2),"")
A40: IMP-04 | B40: INTERMEDIATE | C40: C2 | F40: =IFERROR(I40*D40+J40,"") | G40: =IFERROR(E40-F40,"") | H40: =IFERROR(ROUND(G40/F40*100,2),"") | I40: =IFERROR(SLOPE(E39:E43,D39:D43),"") | J40: =IFERROR(INTERCEPT(E39:E43,D39:D43),"") | K40: =IFERROR(CORREL(E39:E43,D39:D43),"") | L40: =IFERROR(ROUND(J40/E41*100,2),"")
...

Sheet 重复性结果
A1: 重复性结果
A2: impurity_id | B2: sequence | C2: gross_weight | D2: tare_weight | E2: api_weight | F2: retention_time | G2: peak_area | H2: measured_concentration | I2: sample_content | J2: retention_time_rsd | K2: content_rsd | L2: content_ci_low | M2: content_ci_high
A3: 杂质编号 | B3: No. | C3: 毛重（mg） | D3: 扣重（mg） | E3: API质量（mg） | F3: 保留时间（min） | G3: 峰面积 | H3: 测得浓度（ng/ml） | I3: 相当于供试品中含量（ppm） | J3: 保留时间RSD（%） | K3: 含量RSD（%） | L3: 含量95%置信下限 | M3: 含量95%置信上限
A4: IMP-01 | B4: 1 | E4: =IFERROR(C4-D4,"") | I4: =IFERROR(ROUND(H4*20/E4,2),"") | J4: =IFERROR(ROUND(STDEV(F4:F9)/AVERAGE(F4:F9)*100,2),"") | K4: =IFERROR(ROUND(STDEV(I4:I9)/AVERAGE(I4:I9)*100,2),"") | L4: =IFERROR(AVERAGE(I4:I9)-TINV(0.05,COUNT(I4:I9)-1)*STDEV(I4:I9)/SQRT(COUNT(I4:I9)),"") | M4: =IFERROR(AVERAGE(I4:I9)+TINV(0.05,COUNT(I4:I9)-1)*STDEV(I4:I9)/SQRT(COUNT(I4:I9)),"")
A5: IMP-01 | B5: 2 | E5: =IFERROR(C5-D5,"") | I5: =IFERROR(ROUND(H5*20/E5,2),"") | J5: =IFERROR(ROUND(STDEV(F4:F9)/AVERAGE(F4:F9)*100,2),"") | K5: =IFERROR(ROUND(STDEV(I4:I9)/AVERAGE(I4:I9)*100,2),"") | L5: =IFERROR(AVERAGE(I4:I9)-TINV(0.05,COUNT(I4:I9)-1)*STDEV(I4:I9)/SQRT(COUNT(I4:I9)),"") | M5: =IFERROR(AVERAGE(I4:I9)+TINV(0.05,COUNT(I4:I9)-1)*STDEV(I4:I9)/SQRT(COUNT(I4:I9)),"")
A6: IMP-01 | B6: 3 | E6: =IFERROR(C6-D6,"") | I6: =IFERROR(ROUND(H6*20/E6,2),"") | J6: =IFERROR(ROUND(STDEV(F4:F9)/AVERAGE(F4:F9)*100,2),"") | K6: =IFERROR(ROUND(STDEV(I4:I9)/AVERAGE(I4:I9)*100,2),"") | L6: =IFERROR(AVERAGE(I4:I9)-TINV(0.05,COUNT(I4:I9)-1)*STDEV(I4:I9)/SQRT(COUNT(I4:I9)),"") | M6: =IFERROR(AVERAGE(I4:I9)+TINV(0.05,COUNT(I4:I9)-1)*STDEV(I4:I9)/SQRT(COUNT(I4:I9)),"")
A7: IMP-01 | B7: 4 | E7: =IFERROR(C7-D7,"") | I7: =IFERROR(ROUND(H7*20/E7,2),"") | J7: =IFERROR(ROUND(STDEV(F4:F9)/AVERAGE(F4:F9)*100,2),"") | K7: =IFERROR(ROUND(STDEV(I4:I9)/AVERAGE(I4:I9)*100,2),"") | L7: =IFERROR(AVERAGE(I4:I9)-TINV(0.05,COUNT(I4:I9)-1)*STDEV(I4:I9)/SQRT(COUNT(I4:I9)),"") | M7: =IFERROR(AVERAGE(I4:I9)+TINV(0.05,COUNT(I4:I9)-1)*STDEV(I4:I9)/SQRT(COUNT(I4:I9)),"")
A8: IMP-01 | B8: 5 | E8: =IFERROR(C8-D8,"") | I8: =IFERROR(ROUND(H8*20/E8,2),"") | J8: =IFERROR(ROUND(STDEV(F4:F9)/AVERAGE(F4:F9)*100,2),"") | K8: =IFERROR(ROUND(STDEV(I4:I9)/AVERAGE(I4:I9)*100,2),"") | L8: =IFERROR(AVERAGE(I4:I9)-TINV(0.05,COUNT(I4:I9)-1)*STDEV(I4:I9)/SQRT(COUNT(I4:I9)),"") | M8: =IFERROR(AVERAGE(I4:I9)+TINV(0.05,COUNT(I4:I9)-1)*STDEV(I4:I9)/SQRT(COUNT(I4:I9)),"")
A9: IMP-01 | B9: 6 | E9: =IFERROR(C9-D9,"") | I9: =IFERROR(ROUND(H9*20/E9,2),"") | J9: =IFERROR(ROUND(STDEV(F4:F9)/AVERAGE(F4:F9)*100,2),"") | K9: =IFERROR(ROUND(STDEV(I4:I9)/AVERAGE(I4:I9)*100,2),"") | L9: =IFERROR(AVERAGE(I4:I9)-TINV(0.05,COUNT(I4:I9)-1)*STDEV(I4:I9)/SQRT(COUNT(I4:I9)),"") | M9: =IFERROR(AVERAGE(I4:I9)+TINV(0.05,COUNT(I4:I9)-1)*STDEV(I4:I9)/SQRT(COUNT(I4:I9)),"")
A10: IMP-02 | B10: 1 | E10: =IFERROR(C10-D10,"") | I10: =IFERROR(ROUND(H10*20/E10,2),"") | J10: =IFERROR(ROUND(STDEV(F10:F15)/AVERAGE(F10:F15)*100,2),"") | K10: =IFERROR(ROUND(STDEV(I10:I15)/AVERAGE(I10:I15)*100,2),"") | L10: =IFERROR(AVERAGE(I10:I15)-TINV(0.05,COUNT(I10:I15)-1)*STDEV(I10:I15)/SQRT(COUNT(I10:I15)),"") | M10: =IFERROR(AVERAGE(I10:I15)+TINV(0.05,COUNT(I10:I15)-1)*STDEV(I10:I15)/SQRT(COUNT(I10:I15)),"")
A11: IMP-02 | B11: 2 | E11: =IFERROR(C11-D11,"") | I11: =IFERROR(ROUND(H11*20/E11,2),"") | J11: =IFERROR(ROUND(STDEV(F10:F15)/AVERAGE(F10:F15)*100,2),"") | K11: =IFERROR(ROUND(STDEV(I10:I15)/AVERAGE(I10:I15)*100,2),"") | L11: =IFERROR(AVERAGE(I10:I15)-TINV(0.05,COUNT(I10:I15)-1)*STDEV(I10:I15)/SQRT(COUNT(I10:I15)),"") | M11: =IFERROR(AVERAGE(I10:I15)+TINV(0.05,COUNT(I10:I15)-1)*STDEV(I10:I15)/SQRT(COUNT(I10:I15)),"")
A12: IMP-02 | B12: 3 | E12: =IFERROR(C12-D12,"") | I12: =IFERROR(ROUND(H12*20/E12,2),"") | J12: =IFERROR(ROUND(STDEV(F10:F15)/AVERAGE(F10:F15)*100,2),"") | K12: =IFERROR(ROUND(STDEV(I10:I15)/AVERAGE(I10:I15)*100,2),"") | L12: =IFERROR(AVERAGE(I10:I15)-TINV(0.05,COUNT(I10:I15)-1)*STDEV(I10:I15)/SQRT(COUNT(I10:I15)),"") | M12: =IFERROR(AVERAGE(I10:I15)+TINV(0.05,COUNT(I10:I15)-1)*STDEV(I10:I15)/SQRT(COUNT(I10:I15)),"")
A13: IMP-02 | B13: 4 | E13: =IFERROR(C13-D13,"") | I13: =IFERROR(ROUND(H13*20/E13,2),"") | J13: =IFERROR(ROUND(STDEV(F10:F15)/AVERAGE(F10:F15)*100,2),"") | K13: =IFERROR(ROUND(STDEV(I10:I15)/AVERAGE(I10:I15)*100,2),"") | L13: =IFERROR(AVERAGE(I10:I15)-TINV(0.05,COUNT(I10:I15)-1)*STDEV(I10:I15)/SQRT(COUNT(I10:I15)),"") | M13: =IFERROR(AVERAGE(I10:I15)+TINV(0.05,COUNT(I10:I15)-1)*STDEV(I10:I15)/SQRT(COUNT(I10:I15)),"")
A14: IMP-02 | B14: 5 | E14: =IFERROR(C14-D14,"") | I14: =IFERROR(ROUND(H14*20/E14,2),"") | J14: =IFERROR(ROUND(STDEV(F10:F15)/AVERAGE(F10:F15)*100,2),"") | K14: =IFERROR(ROUND(STDEV(I10:I15)/AVERAGE(I10:I15)*100,2),"") | L14: =IFERROR(AVERAGE(I10:I15)-TINV(0.05,COUNT(I10:I15)-1)*STDEV(I10:I15)/SQRT(COUNT(I10:I15)),"") | M14: =IFERROR(AVERAGE(I10:I15)+TINV(0.05,COUNT(I10:I15)-1)*STDEV(I10:I15)/SQRT(COUNT(I10:I15)),"")
A15: IMP-02 | B15: 6 | E15: =IFERROR(C15-D15,"") | I15: =IFERROR(ROUND(H15*20/E15,2),"") | J15: =IFERROR(ROUND(STDEV(F10:F15)/AVERAGE(F10:F15)*100,2),"") | K15: =IFERROR(ROUND(STDEV(I10:I15)/AVERAGE(I10:I15)*100,2),"") | L15: =IFERROR(AVERAGE(I10:I15)-TINV(0.05,COUNT(I10:I15)-1)*STDEV(I10:I15)/SQRT(COUNT(I10:I15)),"") | M15: =IFERROR(AVERAGE(I10:I15)+TINV(0.05,COUNT(I10:I15)-1)*STDEV(I10:I15)/SQRT(COUNT(I10:I15)),"")
A16: IMP-03 | B16: 1 | E16: =IFERROR(C16-D16,"") | I16: =IFERROR(ROUND(H16*20/E16,2),"") | J16: =IFERROR(ROUND(STDEV(F16:F21)/AVERAGE(F16:F21)*100,2),"") | K16: =IFERROR(ROUND(STDEV(I16:I21)/AVERAGE(I16:I21)*100,2),"") | L16: =IFERROR(AVERAGE(I16:I21)-TINV(0.05,COUNT(I16:I21)-1)*STDEV(I16:I21)/SQRT(COUNT(I16:I21)),"") | M16: =IFERROR(AVERAGE(I16:I21)+TINV(0.05,COUNT(I16:I21)-1)*STDEV(I16:I21)/SQRT(COUNT(I16:I21)),"")
A17: IMP-03 | B17: 2 | E17: =IFERROR(C17-D17,"") | I17: =IFERROR(ROUND(H17*20/E17,2),"") | J17: =IFERROR(ROUND(STDEV(F16:F21)/AVERAGE(F16:F21)*100,2),"") | K17: =IFERROR(ROUND(STDEV(I16:I21)/AVERAGE(I16:I21)*100,2),"") | L17: =IFERROR(AVERAGE(I16:I21)-TINV(0.05,COUNT(I16:I21)-1)*STDEV(I16:I21)/SQRT(COUNT(I16:I21)),"") | M17: =IFERROR(AVERAGE(I16:I21)+TINV(0.05,COUNT(I16:I21)-1)*STDEV(I16:I21)/SQRT(COUNT(I16:I21)),"")
A18: IMP-03 | B18: 3 | E18: =IFERROR(C18-D18,"") | I18: =IFERROR(ROUND(H18*20/E18,2),"") | J18: =IFERROR(ROUND(STDEV(F16:F21)/AVERAGE(F16:F21)*100,2),"") | K18: =IFERROR(ROUND(STDEV(I16:I21)/AVERAGE(I16:I21)*100,2),"") | L18: =IFERROR(AVERAGE(I16:I21)-TINV(0.05,COUNT(I16:I21)-1)*STDEV(I16:I21)/SQRT(COUNT(I16:I21)),"") | M18: =IFERROR(AVERAGE(I16:I21)+TINV(0.05,COUNT(I16:I21)-1)*STDEV(I16:I21)/SQRT(COUNT(I16:I21)),"")
A19: IMP-03 | B19: 4 | E19: =IFERROR(C19-D19,"") | I19: =IFERROR(ROUND(H19*20/E19,2),"") | J19: =IFERROR(ROUND(STDEV(F16:F21)/AVERAGE(F16:F21)*100,2),"") | K19: =IFERROR(ROUND(STDEV(I16:I21)/AVERAGE(I16:I21)*100,2),"") | L19: =IFERROR(AVERAGE(I16:I21)-TINV(0.05,COUNT(I16:I21)-1)*STDEV(I16:I21)/SQRT(COUNT(I16:I21)),"") | M19: =IFERROR(AVERAGE(I16:I21)+TINV(0.05,COUNT(I16:I21)-1)*STDEV(I16:I21)/SQRT(COUNT(I16:I21)),"")
A20: IMP-03 | B20: 5 | E20: =IFERROR(C20-D20,"") | I20: =IFERROR(ROUND(H20*20/E20,2),"") | J20: =IFERROR(ROUND(STDEV(F16:F21)/AVERAGE(F16:F21)*100,2),"") | K20: =IFERROR(ROUND(STDEV(I16:I21)/AVERAGE(I16:I21)*100,2),"") | L20: =IFERROR(AVERAGE(I16:I21)-TINV(0.05,COUNT(I16:I21)-1)*STDEV(I16:I21)/SQRT(COUNT(I16:I21)),"") | M20: =IFERROR(AVERAGE(I16:I21)+TINV(0.05,COUNT(I16:I21)-1)*STDEV(I16:I21)/SQRT(COUNT(I16:I21)),"")
A21: IMP-03 | B21: 6 | E21: =IFERROR(C21-D21,"") | I21: =IFERROR(ROUND(H21*20/E21,2),"") | J21: =IFERROR(ROUND(STDEV(F16:F21)/AVERAGE(F16:F21)*100,2),"") | K21: =IFERROR(ROUND(STDEV(I16:I21)/AVERAGE(I16:I21)*100,2),"") | L21: =IFERROR(AVERAGE(I16:I21)-TINV(0.05,COUNT(I16:I21)-1)*STDEV(I16:I21)/SQRT(COUNT(I16:I21)),"") | M21: =IFERROR(AVERAGE(I16:I21)+TINV(0.05,COUNT(I16:I21)-1)*STDEV(I16:I21)/SQRT(COUNT(I16:I21)),"")
A22: IMP-04 | B22: 1 | E22: =IFERROR(C22-D22,"") | I22: =IFERROR(ROUND(H22*20/E22,2),"") | J22: =IFERROR(ROUND(STDEV(F22:F27)/AVERAGE(F22:F27)*100,2),"") | K22: =IFERROR(ROUND(STDEV(I22:I27)/AVERAGE(I22:I27)*100,2),"") | L22: =IFERROR(AVERAGE(I22:I27)-TINV(0.05,COUNT(I22:I27)-1)*STDEV(I22:I27)/SQRT(COUNT(I22:I27)),"") | M22: =IFERROR(AVERAGE(I22:I27)+TINV(0.05,COUNT(I22:I27)-1)*STDEV(I22:I27)/SQRT(COUNT(I22:I27)),"")
A23: IMP-04 | B23: 2 | E23: =IFERROR(C23-D23,"") | I23: =IFERROR(ROUND(H23*20/E23,2),"") | J23: =IFERROR(ROUND(STDEV(F22:F27)/AVERAGE(F22:F27)*100,2),"") | K23: =IFERROR(ROUND(STDEV(I22:I27)/AVERAGE(I22:I27)*100,2),"") | L23: =IFERROR(AVERAGE(I22:I27)-TINV(0.05,COUNT(I22:I27)-1)*STDEV(I22:I27)/SQRT(COUNT(I22:I27)),"") | M23: =IFERROR(AVERAGE(I22:I27)+TINV(0.05,COUNT(I22:I27)-1)*STDEV(I22:I27)/SQRT(COUNT(I22:I27)),"")
A24: IMP-04 | B24: 3 | E24: =IFERROR(C24-D24,"") | I24: =IFERROR(ROUND(H24*20/E24,2),"") | J24: =IFERROR(ROUND(STDEV(F22:F27)/AVERAGE(F22:F27)*100,2),"") | K24: =IFERROR(ROUND(STDEV(I22:I27)/AVERAGE(I22:I27)*100,2),"") | L24: =IFERROR(AVERAGE(I22:I27)-TINV(0.05,COUNT(I22:I27)-1)*STDEV(I22:I27)/SQRT(COUNT(I22:I27)),"") | M24: =IFERROR(AVERAGE(I22:I27)+TINV(0.05,COUNT(I22:I27)-1)*STDEV(I22:I27)/SQRT(COUNT(I22:I27)),"")
A25: IMP-04 | B25: 4 | E25: =IFERROR(C25-D25,"") | I25: =IFERROR(ROUND(H25*20/E25,2),"") | J25: =IFERROR(ROUND(STDEV(F22:F27)/AVERAGE(F22:F27)*100,2),"") | K25: =IFERROR(ROUND(STDEV(I22:I27)/AVERAGE(I22:I27)*100,2),"") | L25: =IFERROR(AVERAGE(I22:I27)-TINV(0.05,COUNT(I22:I27)-1)*STDEV(I22:I27)/SQRT(COUNT(I22:I27)),"") | M25: =IFERROR(AVERAGE(I22:I27)+TINV(0.05,COUNT(I22:I27)-1)*STDEV(I22:I27)/SQRT(COUNT(I22:I27)),"")
A26: IMP-04 | B26: 5 | E26: =IFERROR(C26-D26,"") | I26: =IFERROR(ROUND(H26*20/E26,2),"") | J26: =IFERROR(ROUND(STDEV(F22:F27)/AVERAGE(F22:F27)*100,2),"") | K26: =IFERROR(ROUND(STDEV(I22:I27)/AVERAGE(I22:I27)*100,2),"") | L26: =IFERROR(AVERAGE(I22:I27)-TINV(0.05,COUNT(I22:I27)-1)*STDEV(I22:I27)/SQRT(COUNT(I22:I27)),"") | M26: =IFERROR(AVERAGE(I22:I27)+TINV(0.05,COUNT(I22:I27)-1)*STDEV(I22:I27)/SQRT(COUNT(I22:I27)),"")
A27: IMP-04 | B27: 6 | E27: =IFERROR(C27-D27,"") | I27: =IFERROR(ROUND(H27*20/E27,2),"") | J27: =IFERROR(ROUND(STDEV(F22:F27)/AVERAGE(F22:F27)*100,2),"") | K27: =IFERROR(ROUND(STDEV(I22:I27)/AVERAGE(I22:I27)*100,2),"") | L27: =IFERROR(AVERAGE(I22:I27)-TINV(0.05,COUNT(I22:I27)-1)*STDEV(I22:I27)/SQRT(COUNT(I22:I27)),"") | M27: =IFERROR(AVERAGE(I22:I27)+TINV(0.05,COUNT(I22:I27)-1)*STDEV(I22:I27)/SQRT(COUNT(I22:I27)),"")
A28: IMP-05 | B28: 1 | E28: =IFERROR(C28-D28,"") | I28: =IFERROR(ROUND(H28*20/E28,2),"") | J28: =IFERROR(ROUND(STDEV(F28:F33)/AVERAGE(F28:F33)*100,2),"") | K28: =IFERROR(ROUND(STDEV(I28:I33)/AVERAGE(I28:I33)*100,2),"") | L28: =IFERROR(AVERAGE(I28:I33)-TINV(0.05,COUNT(I28:I33)-1)*STDEV(I28:I33)/SQRT(COUNT(I28:I33)),"") | M28: =IFERROR(AVERAGE(I28:I33)+TINV(0.05,COUNT(I28:I33)-1)*STDEV(I28:I33)/SQRT(COUNT(I28:I33)),"")
A29: IMP-05 | B29: 2 | E29: =IFERROR(C29-D29,"") | I29: =IFERROR(ROUND(H29*20/E29,2),"") | J29: =IFERROR(ROUND(STDEV(F28:F33)/AVERAGE(F28:F33)*100,2),"") | K29: =IFERROR(ROUND(STDEV(I28:I33)/AVERAGE(I28:I33)*100,2),"") | L29: =IFERROR(AVERAGE(I28:I33)-TINV(0.05,COUNT(I28:I33)-1)*STDEV(I28:I33)/SQRT(COUNT(I28:I33)),"") | M29: =IFERROR(AVERAGE(I28:I33)+TINV(0.05,COUNT(I28:I33)-1)*STDEV(I28:I33)/SQRT(COUNT(I28:I33)),"")
A30: IMP-05 | B30: 3 | E30: =IFERROR(C30-D30,"") | I30: =IFERROR(ROUND(H30*20/E30,2),"") | J30: =IFERROR(ROUND(STDEV(F28:F33)/AVERAGE(F28:F33)*100,2),"") | K30: =IFERROR(ROUND(STDEV(I28:I33)/AVERAGE(I28:I33)*100,2),"") | L30: =IFERROR(AVERAGE(I28:I33)-TINV(0.05,COUNT(I28:I33)-1)*STDEV(I28:I33)/SQRT(COUNT(I28:I33)),"") | M30: =IFERROR(AVERAGE(I28:I33)+TINV(0.05,COUNT(I28:I33)-1)*STDEV(I28:I33)/SQRT(COUNT(I28:I33)),"")
A31: IMP-05 | B31: 4 | E31: =IFERROR(C31-D31,"") | I31: =IFERROR(ROUND(H31*20/E31,2),"") | J31: =IFERROR(ROUND(STDEV(F28:F33)/AVERAGE(F28:F33)*100,2),"") | K31: =IFERROR(ROUND(STDEV(I28:I33)/AVERAGE(I28:I33)*100,2),"") | L31: =IFERROR(AVERAGE(I28:I33)-TINV(0.05,COUNT(I28:I33)-1)*STDEV(I28:I33)/SQRT(COUNT(I28:I33)),"") | M31: =IFERROR(AVERAGE(I28:I33)+TINV(0.05,COUNT(I28:I33)-1)*STDEV(I28:I33)/SQRT(COUNT(I28:I33)),"")
A32: IMP-05 | B32: 5 | E32: =IFERROR(C32-D32,"") | I32: =IFERROR(ROUND(H32*20/E32,2),"") | J32: =IFERROR(ROUND(STDEV(F28:F33)/AVERAGE(F28:F33)*100,2),"") | K32: =IFERROR(ROUND(STDEV(I28:I33)/AVERAGE(I28:I33)*100,2),"") | L32: =IFERROR(AVERAGE(I28:I33)-TINV(0.05,COUNT(I28:I33)-1)*STDEV(I28:I33)/SQRT(COUNT(I28:I33)),"") | M32: =IFERROR(AVERAGE(I28:I33)+TINV(0.05,COUNT(I28:I33)-1)*STDEV(I28:I33)/SQRT(COUNT(I28:I33)),"")
A33: IMP-05 | B33: 6 | E33: =IFERROR(C33-D33,"") | I33: =IFERROR(ROUND(H33*20/E33,2),"") | J33: =IFERROR(ROUND(STDEV(F28:F33)/AVERAGE(F28:F33)*100,2),"") | K33: =IFERROR(ROUND(STDEV(I28:I33)/AVERAGE(I28:I33)*100,2),"") | L33: =IFERROR(AVERAGE(I28:I33)-TINV(0.05,COUNT(I28:I33)-1)*STDEV(I28:I33)/SQRT(COUNT(I28:I33)),"") | M33: =IFERROR(AVERAGE(I28:I33)+TINV(0.05,COUNT(I28:I33)-1)*STDEV(I28:I33)/SQRT(COUNT(I28:I33)),"")
A34: IMP-06 | B34: 1 | E34: =IFERROR(C34-D34,"") | I34: =IFERROR(ROUND(H34*20/E34,2),"") | J34: =IFERROR(ROUND(STDEV(F34:F39)/AVERAGE(F34:F39)*100,2),"") | K34: =IFERROR(ROUND(STDEV(I34:I39)/AVERAGE(I34:I39)*100,2),"") | L34: =IFERROR(AVERAGE(I34:I39)-TINV(0.05,COUNT(I34:I39)-1)*STDEV(I34:I39)/SQRT(COUNT(I34:I39)),"") | M34: =IFERROR(AVERAGE(I34:I39)+TINV(0.05,COUNT(I34:I39)-1)*STDEV(I34:I39)/SQRT(COUNT(I34:I39)),"")
A35: IMP-06 | B35: 2 | E35: =IFERROR(C35-D35,"") | I35: =IFERROR(ROUND(H35*20/E35,2),"") | J35: =IFERROR(ROUND(STDEV(F34:F39)/AVERAGE(F34:F39)*100,2),"") | K35: =IFERROR(ROUND(STDEV(I34:I39)/AVERAGE(I34:I39)*100,2),"") | L35: =IFERROR(AVERAGE(I34:I39)-TINV(0.05,COUNT(I34:I39)-1)*STDEV(I34:I39)/SQRT(COUNT(I34:I39)),"") | M35: =IFERROR(AVERAGE(I34:I39)+TINV(0.05,COUNT(I34:I39)-1)*STDEV(I34:I39)/SQRT(COUNT(I34:I39)),"")
A36: IMP-06 | B36: 3 | E36: =IFERROR(C36-D36,"") | I36: =IFERROR(ROUND(H36*20/E36,2),"") | J36: =IFERROR(ROUND(STDEV(F34:F39)/AVERAGE(F34:F39)*100,2),"") | K36: =IFERROR(ROUND(STDEV(I34:I39)/AVERAGE(I34:I39)*100,2),"") | L36: =IFERROR(AVERAGE(I34:I39)-TINV(0.05,COUNT(I34:I39)-1)*STDEV(I34:I39)/SQRT(COUNT(I34:I39)),"") | M36: =IFERROR(AVERAGE(I34:I39)+TINV(0.05,COUNT(I34:I39)-1)*STDEV(I34:I39)/SQRT(COUNT(I34:I39)),"")
A37: IMP-06 | B37: 4 | E37: =IFERROR(C37-D37,"") | I37: =IFERROR(ROUND(H37*20/E37,2),"") | J37: =IFERROR(ROUND(STDEV(F34:F39)/AVERAGE(F34:F39)*100,2),"") | K37: =IFERROR(ROUND(STDEV(I34:I39)/AVERAGE(I34:I39)*100,2),"") | L37: =IFERROR(AVERAGE(I34:I39)-TINV(0.05,COUNT(I34:I39)-1)*STDEV(I34:I39)/SQRT(COUNT(I34:I39)),"") | M37: =IFERROR(AVERAGE(I34:I39)+TINV(0.05,COUNT(I34:I39)-1)*STDEV(I34:I39)/SQRT(COUNT(I34:I39)),"")
A38: IMP-06 | B38: 5 | E38: =IFERROR(C38-D38,"") | I38: =IFERROR(ROUND(H38*20/E38,2),"") | J38: =IFERROR(ROUND(STDEV(F34:F39)/AVERAGE(F34:F39)*100,2),"") | K38: =IFERROR(ROUND(STDEV(I34:I39)/AVERAGE(I34:I39)*100,2),"") | L38: =IFERROR(AVERAGE(I34:I39)-TINV(0.05,COUNT(I34:I39)-1)*STDEV(I34:I39)/SQRT(COUNT(I34:I39)),"") | M38: =IFERROR(AVERAGE(I34:I39)+TINV(0.05,COUNT(I34:I39)-1)*STDEV(I34:I39)/SQRT(COUNT(I34:I39)),"")
A39: IMP-06 | B39: 6 | E39: =IFERROR(C39-D39,"") | I39: =IFERROR(ROUND(H39*20/E39,2),"") | J39: =IFERROR(ROUND(STDEV(F34:F39)/AVERAGE(F34:F39)*100,2),"") | K39: =IFERROR(ROUND(STDEV(I34:I39)/AVERAGE(I34:I39)*100,2),"") | L39: =IFERROR(AVERAGE(I34:I39)-TINV(0.05,COUNT(I34:I39)-1)*STDEV(I34:I39)/SQRT(COUNT(I34:I39)),"") | M39: =IFERROR(AVERAGE(I34:I39)+TINV(0.05,COUNT(I34:I39)-1)*STDEV(I34:I39)/SQRT(COUNT(I34:I39)),"")
A40: IMP-07 | B40: 1 | E40: =IFERROR(C40-D40,"") | I40: =IFERROR(ROUND(H40*20/E40,2),"") | J40: =IFERROR(ROUND(STDEV(F40:F45)/AVERAGE(F40:F45)*100,2),"") | K40: =IFERROR(ROUND(STDEV(I40:I45)/AVERAGE(I40:I45)*100,2),"") | L40: =IFERROR(AVERAGE(I40:I45)-TINV(0.05,COUNT(I40:I45)-1)*STDEV(I40:I45)/SQRT(COUNT(I40:I45)),"") | M40: =IFERROR(AVERAGE(I40:I45)+TINV(0.05,COUNT(I40:I45)-1)*STDEV(I40:I45)/SQRT(COUNT(I40:I45)),"")
...

Sheet 中间精密度结果
A1: 中间精密度结果
A2: impurity_id | B2: operator_or_day | C2: sequence | D2: gross_weight | E2: tare_weight | F2: api_weight | G2: retention_time | H2: peak_area | I2: measured_concentration | J2: sample_content | K2: retention_time_rsd | L2: content_rsd | M2: content_ci_low | N2: content_ci_high
A3: 杂质编号 | B3: 人员/日期组 | C3: No. | D3: 毛重（mg） | E3: 扣重（mg） | F3: API质量（mg） | G3: 保留时间（min） | H3: 峰面积 | I3: 测得浓度（ng/ml） | J3: 相当于供试品中含量（ppm） | K3: 保留时间RSD（%） | L3: 含量RSD（%） | M3: 含量95%置信下限 | N3: 含量95%置信上限
A4: IMP-01 | B4: A | C4: 1 | F4: =IFERROR(D4-E4,"") | J4: =IFERROR(ROUND(I4*20/F4,2),"") | K4: =IFERROR(ROUND(STDEV(G4:G9)/AVERAGE(G4:G9)*100,2),"") | L4: =IFERROR(ROUND(STDEV(J4:J9)/AVERAGE(J4:J9)*100,2),"") | M4: =IFERROR(AVERAGE(J4:J9)-TINV(0.05,COUNT(J4:J9)-1)*STDEV(J4:J9)/SQRT(COUNT(J4:J9)),"") | N4: =IFERROR(AVERAGE(J4:J9)+TINV(0.05,COUNT(J4:J9)-1)*STDEV(J4:J9)/SQRT(COUNT(J4:J9)),"")
A5: IMP-01 | B5: A | C5: 2 | F5: =IFERROR(D5-E5,"") | J5: =IFERROR(ROUND(I5*20/F5,2),"") | K5: =IFERROR(ROUND(STDEV(G4:G9)/AVERAGE(G4:G9)*100,2),"") | L5: =IFERROR(ROUND(STDEV(J4:J9)/AVERAGE(J4:J9)*100,2),"") | M5: =IFERROR(AVERAGE(J4:J9)-TINV(0.05,COUNT(J4:J9)-1)*STDEV(J4:J9)/SQRT(COUNT(J4:J9)),"") | N5: =IFERROR(AVERAGE(J4:J9)+TINV(0.05,COUNT(J4:J9)-1)*STDEV(J4:J9)/SQRT(COUNT(J4:J9)),"")
A6: IMP-01 | B6: A | C6: 3 | F6: =IFERROR(D6-E6,"") | J6: =IFERROR(ROUND(I6*20/F6,2),"") | K6: =IFERROR(ROUND(STDEV(G4:G9)/AVERAGE(G4:G9)*100,2),"") | L6: =IFERROR(ROUND(STDEV(J4:J9)/AVERAGE(J4:J9)*100,2),"") | M6: =IFERROR(AVERAGE(J4:J9)-TINV(0.05,COUNT(J4:J9)-1)*STDEV(J4:J9)/SQRT(COUNT(J4:J9)),"") | N6: =IFERROR(AVERAGE(J4:J9)+TINV(0.05,COUNT(J4:J9)-1)*STDEV(J4:J9)/SQRT(COUNT(J4:J9)),"")
A7: IMP-01 | B7: A | C7: 4 | F7: =IFERROR(D7-E7,"") | J7: =IFERROR(ROUND(I7*20/F7,2),"") | K7: =IFERROR(ROUND(STDEV(G4:G9)/AVERAGE(G4:G9)*100,2),"") | L7: =IFERROR(ROUND(STDEV(J4:J9)/AVERAGE(J4:J9)*100,2),"") | M7: =IFERROR(AVERAGE(J4:J9)-TINV(0.05,COUNT(J4:J9)-1)*STDEV(J4:J9)/SQRT(COUNT(J4:J9)),"") | N7: =IFERROR(AVERAGE(J4:J9)+TINV(0.05,COUNT(J4:J9)-1)*STDEV(J4:J9)/SQRT(COUNT(J4:J9)),"")
A8: IMP-01 | B8: A | C8: 5 | F8: =IFERROR(D8-E8,"") | J8: =IFERROR(ROUND(I8*20/F8,2),"") | K8: =IFERROR(ROUND(STDEV(G4:G9)/AVERAGE(G4:G9)*100,2),"") | L8: =IFERROR(ROUND(STDEV(J4:J9)/AVERAGE(J4:J9)*100,2),"") | M8: =IFERROR(AVERAGE(J4:J9)-TINV(0.05,COUNT(J4:J9)-1)*STDEV(J4:J9)/SQRT(COUNT(J4:J9)),"") | N8: =IFERROR(AVERAGE(J4:J9)+TINV(0.05,COUNT(J4:J9)-1)*STDEV(J4:J9)/SQRT(COUNT(J4:J9)),"")
A9: IMP-01 | B9: A | C9: 6 | F9: =IFERROR(D9-E9,"") | J9: =IFERROR(ROUND(I9*20/F9,2),"") | K9: =IFERROR(ROUND(STDEV(G4:G9)/AVERAGE(G4:G9)*100,2),"") | L9: =IFERROR(ROUND(STDEV(J4:J9)/AVERAGE(J4:J9)*100,2),"") | M9: =IFERROR(AVERAGE(J4:J9)-TINV(0.05,COUNT(J4:J9)-1)*STDEV(J4:J9)/SQRT(COUNT(J4:J9)),"") | N9: =IFERROR(AVERAGE(J4:J9)+TINV(0.05,COUNT(J4:J9)-1)*STDEV(J4:J9)/SQRT(COUNT(J4:J9)),"")
A10: IMP-01 | B10: B | C10: 1 | F10: =IFERROR(D10-E10,"") | J10: =IFERROR(ROUND(I10*20/F10,2),"") | K10: =IFERROR(ROUND(STDEV(G10:G15)/AVERAGE(G10:G15)*100,2),"") | L10: =IFERROR(ROUND(STDEV(J10:J15)/AVERAGE(J10:J15)*100,2),"") | M10: =IFERROR(AVERAGE(J10:J15)-TINV(0.05,COUNT(J10:J15)-1)*STDEV(J10:J15)/SQRT(COUNT(J10:J15)),"") | N10: =IFERROR(AVERAGE(J10:J15)+TINV(0.05,COUNT(J10:J15)-1)*STDEV(J10:J15)/SQRT(COUNT(J10:J15)),"")
A11: IMP-01 | B11: B | C11: 2 | F11: =IFERROR(D11-E11,"") | J11: =IFERROR(ROUND(I11*20/F11,2),"") | K11: =IFERROR(ROUND(STDEV(G10:G15)/AVERAGE(G10:G15)*100,2),"") | L11: =IFERROR(ROUND(STDEV(J10:J15)/AVERAGE(J10:J15)*100,2),"") | M11: =IFERROR(AVERAGE(J10:J15)-TINV(0.05,COUNT(J10:J15)-1)*STDEV(J10:J15)/SQRT(COUNT(J10:J15)),"") | N11: =IFERROR(AVERAGE(J10:J15)+TINV(0.05,COUNT(J10:J15)-1)*STDEV(J10:J15)/SQRT(COUNT(J10:J15)),"")
A12: IMP-01 | B12: B | C12: 3 | F12: =IFERROR(D12-E12,"") | J12: =IFERROR(ROUND(I12*20/F12,2),"") | K12: =IFERROR(ROUND(STDEV(G10:G15)/AVERAGE(G10:G15)*100,2),"") | L12: =IFERROR(ROUND(STDEV(J10:J15)/AVERAGE(J10:J15)*100,2),"") | M12: =IFERROR(AVERAGE(J10:J15)-TINV(0.05,COUNT(J10:J15)-1)*STDEV(J10:J15)/SQRT(COUNT(J10:J15)),"") | N12: =IFERROR(AVERAGE(J10:J15)+TINV(0.05,COUNT(J10:J15)-1)*STDEV(J10:J15)/SQRT(COUNT(J10:J15)),"")
A13: IMP-01 | B13: B | C13: 4 | F13: =IFERROR(D13-E13,"") | J13: =IFERROR(ROUND(I13*20/F13,2),"") | K13: =IFERROR(ROUND(STDEV(G10:G15)/AVERAGE(G10:G15)*100,2),"") | L13: =IFERROR(ROUND(STDEV(J10:J15)/AVERAGE(J10:J15)*100,2),"") | M13: =IFERROR(AVERAGE(J10:J15)-TINV(0.05,COUNT(J10:J15)-1)*STDEV(J10:J15)/SQRT(COUNT(J10:J15)),"") | N13: =IFERROR(AVERAGE(J10:J15)+TINV(0.05,COUNT(J10:J15)-1)*STDEV(J10:J15)/SQRT(COUNT(J10:J15)),"")
A14: IMP-01 | B14: B | C14: 5 | F14: =IFERROR(D14-E14,"") | J14: =IFERROR(ROUND(I14*20/F14,2),"") | K14: =IFERROR(ROUND(STDEV(G10:G15)/AVERAGE(G10:G15)*100,2),"") | L14: =IFERROR(ROUND(STDEV(J10:J15)/AVERAGE(J10:J15)*100,2),"") | M14: =IFERROR(AVERAGE(J10:J15)-TINV(0.05,COUNT(J10:J15)-1)*STDEV(J10:J15)/SQRT(COUNT(J10:J15)),"") | N14: =IFERROR(AVERAGE(J10:J15)+TINV(0.05,COUNT(J10:J15)-1)*STDEV(J10:J15)/SQRT(COUNT(J10:J15)),"")
A15: IMP-01 | B15: B | C15: 6 | F15: =IFERROR(D15-E15,"") | J15: =IFERROR(ROUND(I15*20/F15,2),"") | K15: =IFERROR(ROUND(STDEV(G10:G15)/AVERAGE(G10:G15)*100,2),"") | L15: =IFERROR(ROUND(STDEV(J10:J15)/AVERAGE(J10:J15)*100,2),"") | M15: =IFERROR(AVERAGE(J10:J15)-TINV(0.05,COUNT(J10:J15)-1)*STDEV(J10:J15)/SQRT(COUNT(J10:J15)),"") | N15: =IFERROR(AVERAGE(J10:J15)+TINV(0.05,COUNT(J10:J15)-1)*STDEV(J10:J15)/SQRT(COUNT(J10:J15)),"")
A16: IMP-02 | B16: A | C16: 1 | F16: =IFERROR(D16-E16,"") | J16: =IFERROR(ROUND(I16*20/F16,2),"") | K16: =IFERROR(ROUND(STDEV(G16:G21)/AVERAGE(G16:G21)*100,2),"") | L16: =IFERROR(ROUND(STDEV(J16:J21)/AVERAGE(J16:J21)*100,2),"") | M16: =IFERROR(AVERAGE(J16:J21)-TINV(0.05,COUNT(J16:J21)-1)*STDEV(J16:J21)/SQRT(COUNT(J16:J21)),"") | N16: =IFERROR(AVERAGE(J16:J21)+TINV(0.05,COUNT(J16:J21)-1)*STDEV(J16:J21)/SQRT(COUNT(J16:J21)),"")
A17: IMP-02 | B17: A | C17: 2 | F17: =IFERROR(D17-E17,"") | J17: =IFERROR(ROUND(I17*20/F17,2),"") | K17: =IFERROR(ROUND(STDEV(G16:G21)/AVERAGE(G16:G21)*100,2),"") | L17: =IFERROR(ROUND(STDEV(J16:J21)/AVERAGE(J16:J21)*100,2),"") | M17: =IFERROR(AVERAGE(J16:J21)-TINV(0.05,COUNT(J16:J21)-1)*STDEV(J16:J21)/SQRT(COUNT(J16:J21)),"") | N17: =IFERROR(AVERAGE(J16:J21)+TINV(0.05,COUNT(J16:J21)-1)*STDEV(J16:J21)/SQRT(COUNT(J16:J21)),"")
A18: IMP-02 | B18: A | C18: 3 | F18: =IFERROR(D18-E18,"") | J18: =IFERROR(ROUND(I18*20/F18,2),"") | K18: =IFERROR(ROUND(STDEV(G16:G21)/AVERAGE(G16:G21)*100,2),"") | L18: =IFERROR(ROUND(STDEV(J16:J21)/AVERAGE(J16:J21)*100,2),"") | M18: =IFERROR(AVERAGE(J16:J21)-TINV(0.05,COUNT(J16:J21)-1)*STDEV(J16:J21)/SQRT(COUNT(J16:J21)),"") | N18: =IFERROR(AVERAGE(J16:J21)+TINV(0.05,COUNT(J16:J21)-1)*STDEV(J16:J21)/SQRT(COUNT(J16:J21)),"")
A19: IMP-02 | B19: A | C19: 4 | F19: =IFERROR(D19-E19,"") | J19: =IFERROR(ROUND(I19*20/F19,2),"") | K19: =IFERROR(ROUND(STDEV(G16:G21)/AVERAGE(G16:G21)*100,2),"") | L19: =IFERROR(ROUND(STDEV(J16:J21)/AVERAGE(J16:J21)*100,2),"") | M19: =IFERROR(AVERAGE(J16:J21)-TINV(0.05,COUNT(J16:J21)-1)*STDEV(J16:J21)/SQRT(COUNT(J16:J21)),"") | N19: =IFERROR(AVERAGE(J16:J21)+TINV(0.05,COUNT(J16:J21)-1)*STDEV(J16:J21)/SQRT(COUNT(J16:J21)),"")
A20: IMP-02 | B20: A | C20: 5 | F20: =IFERROR(D20-E20,"") | J20: =IFERROR(ROUND(I20*20/F20,2),"") | K20: =IFERROR(ROUND(STDEV(G16:G21)/AVERAGE(G16:G21)*100,2),"") | L20: =IFERROR(ROUND(STDEV(J16:J21)/AVERAGE(J16:J21)*100,2),"") | M20: =IFERROR(AVERAGE(J16:J21)-TINV(0.05,COUNT(J16:J21)-1)*STDEV(J16:J21)/SQRT(COUNT(J16:J21)),"") | N20: =IFERROR(AVERAGE(J16:J21)+TINV(0.05,COUNT(J16:J21)-1)*STDEV(J16:J21)/SQRT(COUNT(J16:J21)),"")
A21: IMP-02 | B21: A | C21: 6 | F21: =IFERROR(D21-E21,"") | J21: =IFERROR(ROUND(I21*20/F21,2),"") | K21: =IFERROR(ROUND(STDEV(G16:G21)/AVERAGE(G16:G21)*100,2),"") | L21: =IFERROR(ROUND(STDEV(J16:J21)/AVERAGE(J16:J21)*100,2),"") | M21: =IFERROR(AVERAGE(J16:J21)-TINV(0.05,COUNT(J16:J21)-1)*STDEV(J16:J21)/SQRT(COUNT(J16:J21)),"") | N21: =IFERROR(AVERAGE(J16:J21)+TINV(0.05,COUNT(J16:J21)-1)*STDEV(J16:J21)/SQRT(COUNT(J16:J21)),"")
A22: IMP-02 | B22: B | C22: 1 | F22: =IFERROR(D22-E22,"") | J22: =IFERROR(ROUND(I22*20/F22,2),"") | K22: =IFERROR(ROUND(STDEV(G22:G27)/AVERAGE(G22:G27)*100,2),"") | L22: =IFERROR(ROUND(STDEV(J22:J27)/AVERAGE(J22:J27)*100,2),"") | M22: =IFERROR(AVERAGE(J22:J27)-TINV(0.05,COUNT(J22:J27)-1)*STDEV(J22:J27)/SQRT(COUNT(J22:J27)),"") | N22: =IFERROR(AVERAGE(J22:J27)+TINV(0.05,COUNT(J22:J27)-1)*STDEV(J22:J27)/SQRT(COUNT(J22:J27)),"")
A23: IMP-02 | B23: B | C23: 2 | F23: =IFERROR(D23-E23,"") | J23: =IFERROR(ROUND(I23*20/F23,2),"") | K23: =IFERROR(ROUND(STDEV(G22:G27)/AVERAGE(G22:G27)*100,2),"") | L23: =IFERROR(ROUND(STDEV(J22:J27)/AVERAGE(J22:J27)*100,2),"") | M23: =IFERROR(AVERAGE(J22:J27)-TINV(0.05,COUNT(J22:J27)-1)*STDEV(J22:J27)/SQRT(COUNT(J22:J27)),"") | N23: =IFERROR(AVERAGE(J22:J27)+TINV(0.05,COUNT(J22:J27)-1)*STDEV(J22:J27)/SQRT(COUNT(J22:J27)),"")
A24: IMP-02 | B24: B | C24: 3 | F24: =IFERROR(D24-E24,"") | J24: =IFERROR(ROUND(I24*20/F24,2),"") | K24: =IFERROR(ROUND(STDEV(G22:G27)/AVERAGE(G22:G27)*100,2),"") | L24: =IFERROR(ROUND(STDEV(J22:J27)/AVERAGE(J22:J27)*100,2),"") | M24: =IFERROR(AVERAGE(J22:J27)-TINV(0.05,COUNT(J22:J27)-1)*STDEV(J22:J27)/SQRT(COUNT(J22:J27)),"") | N24: =IFERROR(AVERAGE(J22:J27)+TINV(0.05,COUNT(J22:J27)-1)*STDEV(J22:J27)/SQRT(COUNT(J22:J27)),"")
